Workbook

Sheet IMS
A1: (Partner Name) in partnership with Medical Aid for Palestinains- MAP UK | L1: المصدر | M1: شمال Gaza City | P1: غير معدي | Q1: FM- NCD | R1: ANC | S1: Dressing | T1: Screening | U1: Screening | AM1: فحص | AU1: فحص سوء التغذية
A2: Project: | C2: Improving Access to Comprehensive Primary Health Care and Protection in Gaza | L2: Alzawida | M2: Gaza City | O2: قبل الحمل | P2: PCC | Q2: FM- CD | R2: PNC | S2: Follow-up Dressing | T2: Screening and Referral | U2: SAM referral | AM2: تحويل SAM | AU2: سوء تغذية شديد
A3: Partner: | L3: Dier Albalah | M3: الزهراء | Q3: ENT | R3: FP | S3: Wound Cleaning | U3: MAM referral | AM3: تحويل MAM | AU3: سوء تغذية متوسط
A4: Medical Point: | L4: خانيونس | M4: Alnussirat | Q4: Derma | R4: GYN | S4: Suture Removal | AM4: —
A5: Month | L5: مواصي خانيونس | M5: Alburaij
A6: Governorate | L6: رفح | M6: Almaghazi | P6: Displaced | Q6: Service Matrix | W6: موعد الحجز
A7: # | B7: Full Name/الإسم الكامل | C7: Visit Date/تاريخ الزيارة | D7: Last Visit Date/تاريخ آخر زيارة | E7: ID N./رقم الهوية | F7: Date of Birth/ تاريخ الميلاد | G7: Age/العمر | H7: Age Group/الفئة العمرية | I7: Gender/الجنس | J7: Gender_N | K7: Phone N./الهاتف | L7: Governorate/المحافظة | M7: Social Status/الحالة الاجتماعية | N7: Disability Status/الإعاقة | O7: Disability Type/نوع الإعاقة | P7: Displacment Tracker | Q7: FM services | R7: SRH services | S7: Wound Care | T7: Breast Cancer | U7: Mal-Nutirition | V7: Referral/التحويلات | W7: Follow-up Date/موعد المتابعة | X7: Visitor Code/رمز الزائر | Y7: FM-N | Z7: SRH-N | AA7: Other1_N | AB7: Other2_N | AC7: Other3_N | AD7: Unique Flag | AE7: Visit Month | AF7: Unique in Month Flag | AG7: First Time in Project Flag
A8: 1 | B8: ليلى عثمان مصطفى دويك | C8: 46110 | D8: {=IFERROR( LOOKUP(2, 1/((TRIM(IMS!$E$8:$E$4000)=TRIM(IMS!$E8))*(IMS!$C$8:$C$4000<IMS!$C8)), IMS!$C$8:$C$4000), "")} | E8: 906767975 | F8: 30025 | G8: 44 | H8: =IF(G8="","",IF(G8<=5,"0-5",IF(G8<=18,"6-18",IF(G8<=60,"19-60","+60")))) -> 19-60 | I8: FEMALE | J8: =IF(OR(LOWER(TRIM(SUBSTITUTE(SUBSTITUTE($I8,CHAR(160)," "),_xludf.UNICHAR(8239)," ")))="male", LOWER(TRIM(SUBSTITUTE(SUBSTITUTE($I8,CHAR(160)," "),_xludf.UNICHAR(8239)," ")))="m", LOWER(TRIM(SUBSTITUTE(SUBSTITUTE($I8,CHAR(160)," "),_xludf.UNICHAR(8239)," ")))="males"), "male", IF(OR(LOWER(TRIM(SUBSTITUTE(SUBSTITUTE($I8,CHAR(160)," "),_xludf.UNICHAR(8239)," ")))="female", LOWER(TRIM(SUBSTITUTE(SUBSTITUTE($I8,CHAR(160)," "),_xludf.UNICHAR(8239)," ")))="f", LOWER(TRIM(SUBSTITUTE(SUBSTITUTE($I8,CHAR(160)," "),_xludf.UNICHAR(8239)," ")))="females"), "female", "")) -> #NAME? | K8: 599860312 | L8: Alnussirat | M8: Married | N8: No | P8: Displaced | Q8: FM- NCD | X8: =IF(E8="","",UPPER(LEFT($C$3,1)&"-"&LEFT($C$4,1)&"-"&TEXT(ROW(A1),"000")&"-"&TEXT(C8,"dd-mm"))) -> --001-29-03 | Y8: =TRIM(SUBSTITUTE(SUBSTITUTE(OFFSET($Q8,0,COLUMN()-COLUMN($AL$1)),CHAR(160)," "),_xludf.UNICHAR(8239)," ")) -> #NAME? | Z8: =TRIM(SUBSTITUTE(SUBSTITUTE(OFFSET($Q8,0,COLUMN()-COLUMN($AL$1)),CHAR(160)," "),_xludf.UNICHAR(8239)," ")) -> #NAME? | AA8: =TRIM(SUBSTITUTE(SUBSTITUTE(OFFSET($Q8,0,COLUMN()-COLUMN($AL$1)),CHAR(160)," "),_xludf.UNICHAR(8239)," ")) -> #NAME? | AB8: =TRIM(SUBSTITUTE(SUBSTITUTE(OFFSET($Q8,0,COLUMN()-COLUMN($AL$1)),CHAR(160)," "),_xludf.UNICHAR(8239)," ")) -> #NAME? | AC8: =TRIM(SUBSTITUTE(SUBSTITUTE(OFFSET($Q8,0,COLUMN()-COLUMN($AL$1)),CHAR(160)," "),_xludf.UNICHAR(8239)," ")) -> #NAME? | AD8: =IF($E8="",0,--(COUNTIFS($E:$E,$E8,$C:$C,">"&$C8)+COUNTIFS($E$8:E8,$E8,$C$8:C8,$C8)=1)) -> 1 | AE8: =IF($C8="","",TEXT($C8,"yyyy-mm")) -> 2026-03 | AF8: =IF(OR($E8="",$AE8=""),0,IF(COUNTIFS($E$8:E8,$E8,$AE$8:AE8,$AE8)=1,1,0)) -> 1 | AG8: =IF($E8="",0,IF(COUNTIF($E$8:E8,$E8)=1,1,0)) -> 1
A9: 2 | B9: هند دياب عبدالكريم اخروات | C9: 46110 | D9: {=IFERROR( LOOKUP(2, 1/((TRIM(IMS!$E$8:$E$4000)=TRIM(IMS!$E9))*(IMS!$C$8:$C$4000<IMS!$C9)), IMS!$C$8:$C$4000), "")} | E9: 934331950 | F9: 27355 | G9: 52 | H9: =IF(G9="","",IF(G9<=5,"0-5",IF(G9<=18,"6-18",IF(G9<=60,"19-60","+60")))) -> 19-60 | I9: FEMALE | J9: =IF(OR(LOWER(TRIM(SUBSTITUTE(SUBSTITUTE($I9,CHAR(160)," "),_xludf.UNICHAR(8239)," ")))="male", LOWER(TRIM(SUBSTITUTE(SUBSTITUTE($I9,CHAR(160)," "),_xludf.UNICHAR(8239)," ")))="m", LOWER(TRIM(SUBSTITUTE(SUBSTITUTE($I9,CHAR(160)," "),_xludf.UNICHAR(8239)," ")))="males"), "male", IF(OR(LOWER(TRIM(SUBSTITUTE(SUBSTITUTE($I9,CHAR(160)," "),_xludf.UNICHAR(8239)," ")))="female", LOWER(TRIM(SUBSTITUTE(SUBSTITUTE($I9,CHAR(160)," "),_xludf.UNICHAR(8239)," ")))="f", LOWER(TRIM(SUBSTITUTE(SUBSTITUTE($I9,CHAR(160)," "),_xludf.UNICHAR(8239)," ")))="females"), "female", "")) -> #NAME? | K9: 596496598 | L9: Alnussirat | M9: Married | N9: No | P9: Displaced | Q9: FM- NCD | X9: =IF(E9="","",UPPER(LEFT($C$3,1)&"-"&LEFT($C$4,1)&"-"&TEXT(ROW(A2),"000")&"-"&TEXT(C9,"dd-mm"))) -> --002-29-03 | Y9: =TRIM(SUBSTITUTE(SUBSTITUTE(OFFSET($Q9,0,COLUMN()-COLUMN($AL$1)),CHAR(160)," "),_xludf.UNICHAR(8239)," ")) -> #NAME? | Z9: =TRIM(SUBSTITUTE(SUBSTITUTE(OFFSET($Q9,0,COLUMN()-COLUMN($AL$1)),CHAR(160)," "),_xludf.UNICHAR(8239)," ")) -> #NAME? | AA9: =TRIM(SUBSTITUTE(SUBSTITUTE(OFFSET($Q9,0,COLUMN()-COLUMN($AL$1)),CHAR(160)," "),_xludf.UNICHAR(8239)," ")) -> #NAME? | AB9: =TRIM(SUBSTITUTE(SUBSTITUTE(OFFSET($Q9,0,COLUMN()-COLUMN($AL$1)),CHAR(160)," "),_xludf.UNICHAR(8239)," ")) -> #NAME? | AC9: =TRIM(SUBSTITUTE(SUBSTITUTE(OFFSET($Q9,0,COLUMN()-COLUMN($AL$1)),CHAR(160)," "),_xludf.UNICHAR(8239)," ")) -> #NAME? | AD9: =IF($E9="",0,--(COUNTIFS($E:$E,$E9,$C:$C,">"&$C9)+COUNTIFS($E$8:E9,$E9,$C$8:C9,$C9)=1)) -> 0 | AE9: =IF($C9="","",TEXT($C9,"yyyy-mm")) -> 2026-03 | AF9: =IF(OR($E9="",$AE9=""),0,IF(COUNTIFS($E$8:E9,$E9,$AE$8:AE9,$AE9)=1,1,0)) -> 1 | AG9: =IF($E9="",0,IF(COUNTIF($E$8:E9,$E9)=1,1,0)) -> 1
A10: 3 | B10: احمد محمد صلاح حمدان | C10: 46110 | D10: {=IFERROR( LOOKUP(2, 1/((TRIM(IMS!$E$8:$E$4000)=TRIM(IMS!$E10))*(IMS!$C$8:$C$4000<IMS!$C10)), IMS!$C$8:$C$4000), "")} | E10: 445807084 | F10: 45115 | G10: 3 | H10: =IF(G10="","",IF(G10<=5,"0-5",IF(G10<=18,"6-18",IF(G10<=60,"19-60","+60")))) -> 0-5 | I10: Male | J10: =IF(OR(LOWER(TRIM(SUBSTITUTE(SUBSTITUTE($I10,CHAR(160)," "),_xludf.UNICHAR(8239)," ")))="male", LOWER(TRIM(SUBSTITUTE(SUBSTITUTE($I10,CHAR(160)," "),_xludf.UNICHAR(8239)," ")))="m", LOWER(TRIM(SUBSTITUTE(SUBSTITUTE($I10,CHAR(160)," "),_xludf.UNICHAR(8239)," ")))="males"), "male", IF(OR(LOWER(TRIM(SUBSTITUTE(SUBSTITUTE($I10,CHAR(160)," "),_xludf.UNICHAR(8239)," ")))="female", LOWER(TRIM(SUBSTITUTE(SUBSTITUTE($I10,CHAR(160)," "),_xludf.UNICHAR(8239)," ")))="f", LOWER(TRIM(SUBSTITUTE(SUBSTITUTE($I10,CHAR(160)," "),_xludf.UNICHAR(8239)," ")))="females"), "female", "")) -> #NAME? | K10: 595781051 | L10: Alnussirat | M10: N/A | N10: Yes | O10: Physical Disability | P10: Displaced | Q10: FM- CD | U10: Screening | X10: =IF(E10="","",UPPER(LEFT($C$3,1)&"-"&LEFT($C$4,1)&"-"&TEXT(ROW(A3),"000")&"-"&TEXT(C10,"dd-mm"))) -> --003-29-03 | Y10: =TRIM(SUBSTITUTE(SUBSTITUTE(OFFSET($Q10,0,COLUMN()-COLUMN($AL$1)),CHAR(160)," "),_xludf.UNICHAR(8239)," ")) -> #NAME? | Z10: =TRIM(SUBSTITUTE(SUBSTITUTE(OFFSET($Q10,0,COLUMN()-COLUMN($AL$1)),CHAR(160)," "),_xludf.UNICHAR(8239)," ")) -> #NAME? | AA10: =TRIM(SUBSTITUTE(SUBSTITUTE(OFFSET($Q10,0,COLUMN()-COLUMN($AL$1)),CHAR(160)," "),_xludf.UNICHAR(8239)," ")) -> #NAME? | AB10: =TRIM(SUBSTITUTE(SUBSTITUTE(OFFSET($Q10,0,COLUMN()-COLUMN($AL$1)),CHAR(160)," "),_xludf.UNICHAR(8239)," ")) -> #NAME? | AC10: =TRIM(SUBSTITUTE(SUBSTITUTE(OFFSET($Q10,0,COLUMN()-COLUMN($AL$1)),CHAR(160)," "),_xludf.UNICHAR(8239)," ")) -> #NAME? | AD10: =IF($E10="",0,--(COUNTIFS($E:$E,$E10,$C:$C,">"&$C10)+COUNTIFS($E$8:E10,$E10,$C$8:C10,$C10)=1)) -> 1 | AE10: =IF($C10="","",TEXT($C10,"yyyy-mm")) -> 2026-03 | AF10: =IF(OR($E10="",$AE10=""),0,IF(COUNTIFS($E$8:E10,$E10,$AE$8:AE10,$AE10)=1,1,0)) -> 1 | AG10: =IF($E10="",0,IF(COUNTIF($E$8:E10,$E10)=1,1,0)) -> 1
A11: 4 | B11: اخلاص محمود عبد حمدان | C11: 46110 | D11: {=IFERROR( LOOKUP(2, 1/((TRIM(IMS!$E$8:$E$4000)=TRIM(IMS!$E11))*(IMS!$C$8:$C$4000<IMS!$C11)), IMS!$C$8:$C$4000), "")} | E11: 803589548 | F11: 34019 | G11: 33 | H11: =IF(G11="","",IF(G11<=5,"0-5",IF(G11<=18,"6-18",IF(G11<=60,"19-60","+60")))) -> 19-60 | I11: FEMALE | J11: =IF(OR(LOWER(TRIM(SUBSTITUTE(SUBSTITUTE($I11,CHAR(160)," "),_xludf.UNICHAR(8239)," ")))="male", LOWER(TRIM(SUBSTITUTE(SUBSTITUTE($I11,CHAR(160)," "),_xludf.UNICHAR(8239)," ")))="m", LOWER(TRIM(SUBSTITUTE(SUBSTITUTE($I11,CHAR(160)," "),_xludf.UNICHAR(8239)," ")))="males"), "male", IF(OR(LOWER(TRIM(SUBSTITUTE(SUBSTITUTE($I11,CHAR(160)," "),_xludf.UNICHAR(8239)," ")))="female", LOWER(TRIM(SUBSTITUTE(SUBSTITUTE($I11,CHAR(160)," "),_xludf.UNICHAR(8239)," ")))="f", LOWER(TRIM(SUBSTITUTE(SUBSTITUTE($I11,CHAR(160)," "),_xludf.UNICHAR(8239)," ")))="females"), "female", "")) -> #NAME? | K11: 535781051 | L11: Alnussirat | M11: Married | N11: No | P11: Displaced | R11: GYN | X11: =IF(E11="","",UPPER(LEFT($C$3,1)&"-"&LEFT($C$4,1)&"-"&TEXT(ROW(A4),"000")&"-"&TEXT(C11,"dd-mm"))) -> --004-29-03 | Y11: =TRIM(SUBSTITUTE(SUBSTITUTE(OFFSET($Q11,0,COLUMN()-COLUMN($AL$1)),CHAR(160)," "),_xludf.UNICHAR(8239)," ")) -> #NAME? | Z11: =TRIM(SUBSTITUTE(SUBSTITUTE(OFFSET($Q11,0,COLUMN()-COLUMN($AL$1)),CHAR(160)," "),_xludf.UNICHAR(8239)," ")) -> #NAME? | AA11: =TRIM(SUBSTITUTE(SUBSTITUTE(OFFSET($Q11,0,COLUMN()-COLUMN($AL$1)),CHAR(160)," "),_xludf.UNICHAR(8239)," ")) -> #NAME? | AB11: =TRIM(SUBSTITUTE(SUBSTITUTE(OFFSET($Q11,0,COLUMN()-COLUMN($AL$1)),CHAR(160)," "),_xludf.UNICHAR(8239)," ")) -> #NAME? | AC11: =TRIM(SUBSTITUTE(SUBSTITUTE(OFFSET($Q11,0,COLUMN()-COLUMN($AL$1)),CHAR(160)," "),_xludf.UNICHAR(8239)," ")) -> #NAME? | AD11: =IF($E11="",0,--(COUNTIFS($E:$E,$E11,$C:$C,">"&$C11)+COUNTIFS($E$8:E11,$E11,$C$8:C11,$C11)=1)) -> 0 | AE11: =IF($C11="","",TEXT($C11,"yyyy-mm")) -> 2026-03 | AF11: =IF(OR($E11="",$AE11=""),0,IF(COUNTIFS($E$8:E11,$E11,$AE$8:AE11,$AE11)=1,1,0)) -> 1 | AG11: =IF($E11="",0,IF(COUNTIF($E$8:E11,$E11)=1,1,0)) -> 1
A12: 5 | B12: سجى حسين محمد عوض | C12: 46110 | D12: {=IFERROR( LOOKUP(2, 1/((TRIM(IMS!$E$8:$E$4000)=TRIM(IMS!$E12))*(IMS!$C$8:$C$4000<IMS!$C12)), IMS!$C$8:$C$4000), "")} | E12: 425894557 | F12: 39696 | G12: 18 | H12: =IF(G12="","",IF(G12<=5,"0-5",IF(G12<=18,"6-18",IF(G12<=60,"19-60","+60")))) -> 6-18 | I12: FEMALE | J12: =IF(OR(LOWER(TRIM(SUBSTITUTE(SUBSTITUTE($I12,CHAR(160)," "),_xludf.UNICHAR(8239)," ")))="male", LOWER(TRIM(SUBSTITUTE(SUBSTITUTE($I12,CHAR(160)," "),_xludf.UNICHAR(8239)," ")))="m", LOWER(TRIM(SUBSTITUTE(SUBSTITUTE($I12,CHAR(160)," "),_xludf.UNICHAR(8239)," ")))="males"), "male", IF(OR(LOWER(TRIM(SUBSTITUTE(SUBSTITUTE($I12,CHAR(160)," "),_xludf.UNICHAR(8239)," ")))="female", LOWER(TRIM(SUBSTITUTE(SUBSTITUTE($I12,CHAR(160)," "),_xludf.UNICHAR(8239)," ")))="f", LOWER(TRIM(SUBSTITUTE(SUBSTITUTE($I12,CHAR(160)," "),_xludf.UNICHAR(8239)," ")))="females"), "female", "")) -> #NAME? | K12: 598985336 | L12: Alnussirat | M12: Single | N12: No | P12: Displaced | Q12: FM- NCD | X12: =IF(E12="","",UPPER(LEFT($C$3,1)&"-"&LEFT($C$4,1)&"-"&TEXT(ROW(A5),"000")&"-"&TEXT(C12,"dd-mm"))) -> --005-29-03 | Y12: =TRIM(SUBSTITUTE(SUBSTITUTE(OFFSET($Q12,0,COLUMN()-COLUMN($AL$1)),CHAR(160)," "),_xludf.UNICHAR(8239)," ")) -> #NAME? | Z12: =TRIM(SUBSTITUTE(SUBSTITUTE(OFFSET($Q12,0,COLUMN()-COLUMN($AL$1)),CHAR(160)," "),_xludf.UNICHAR(8239)," ")) -> #NAME? | AA12: =TRIM(SUBSTITUTE(SUBSTITUTE(OFFSET($Q12,0,COLUMN()-COLUMN($AL$1)),CHAR(160)," "),_xludf.UNICHAR(8239)," ")) -> #NAME? | AB12: =TRIM(SUBSTITUTE(SUBSTITUTE(OFFSET($Q12,0,COLUMN()-COLUMN($AL$1)),CHAR(160)," "),_xludf.UNICHAR(8239)," ")) -> #NAME? | AC12: =TRIM(SUBSTITUTE(SUBSTITUTE(OFFSET($Q12,0,COLUMN()-COLUMN($AL$1)),CHAR(160)," "),_xludf.UNICHAR(8239)," ")) -> #NAME? | AD12: =IF($E12="",0,--(COUNTIFS($E:$E,$E12,$C:$C,">"&$C12)+COUNTIFS($E$8:E12,$E12,$C$8:C12,$C12)=1)) -> 0 | AE12: =IF($C12="","",TEXT($C12,"yyyy-mm")) -> 2026-03 | AF12: =IF(OR($E12="",$AE12=""),0,IF(COUNTIFS($E$8:E12,$E12,$AE$8:AE12,$AE12)=1,1,0)) -> 1 | AG12: =IF($E12="",0,IF(COUNTIF($E$8:E12,$E12)=1,1,0)) -> 1
A13: 6 | B13: نصرة رمزى نصر عطاالله | C13: 46110 | D13: {=IFERROR( LOOKUP(2, 1/((TRIM(IMS!$E$8:$E$4000)=TRIM(IMS!$E13))*(IMS!$C$8:$C$4000<IMS!$C13)), IMS!$C$8:$C$4000), "")} | E13: 442848636 | F13: 44374 | G13: 5 | H13: =IF(G13="","",IF(G13<=5,"0-5",IF(G13<=18,"6-18",IF(G13<=60,"19-60","+60")))) -> 0-5 | I13: FEMALE | J13: =IF(OR(LOWER(TRIM(SUBSTITUTE(SUBSTITUTE($I13,CHAR(160)," "),_xludf.UNICHAR(8239)," ")))="male", LOWER(TRIM(SUBSTITUTE(SUBSTITUTE($I13,CHAR(160)," "),_xludf.UNICHAR(8239)," ")))="m", LOWER(TRIM(SUBSTITUTE(SUBSTITUTE($I13,CHAR(160)," "),_xludf.UNICHAR(8239)," ")))="males"), "male", IF(OR(LOWER(TRIM(SUBSTITUTE(SUBSTITUTE($I13,CHAR(160)," "),_xludf.UNICHAR(8239)," ")))="female", LOWER(TRIM(SUBSTITUTE(SUBSTITUTE($I13,CHAR(160)," "),_xludf.UNICHAR(8239)," ")))="f", LOWER(TRIM(SUBSTITUTE(SUBSTITUTE($I13,CHAR(160)," "),_xludf.UNICHAR(8239)," ")))="females"), "female", "")) -> #NAME? | K13: 597714853 | L13: Alnussirat | M13: N/A | N13: No | P13: Displaced | Q13: FM- CD | U13: Screening | X13: =IF(E13="","",UPPER(LEFT($C$3,1)&"-"&LEFT($C$4,1)&"-"&TEXT(ROW(A6),"000")&"-"&TEXT(C13,"dd-mm"))) -> --006-29-03 | Y13: =TRIM(SUBSTITUTE(SUBSTITUTE(OFFSET($Q13,0,COLUMN()-COLUMN($AL$1)),CHAR(160)," "),_xludf.UNICHAR(8239)," ")) -> #NAME? | Z13: =TRIM(SUBSTITUTE(SUBSTITUTE(OFFSET($Q13,0,COLUMN()-COLUMN($AL$1)),CHAR(160)," "),_xludf.UNICHAR(8239)," ")) -> #NAME? | AA13: =TRIM(SUBSTITUTE(SUBSTITUTE(OFFSET($Q13,0,COLUMN()-COLUMN($AL$1)),CHAR(160)," "),_xludf.UNICHAR(8239)," ")) -> #NAME? | AB13: =TRIM(SUBSTITUTE(SUBSTITUTE(OFFSET($Q13,0,COLUMN()-COLUMN($AL$1)),CHAR(160)," "),_xludf.UNICHAR(8239)," ")) -> #NAME? | AC13: =TRIM(SUBSTITUTE(SUBSTITUTE(OFFSET($Q13,0,COLUMN()-COLUMN($AL$1)),CHAR(160)," "),_xludf.UNICHAR(8239)," ")) -> #NAME? | AD13: =IF($E13="",0,--(COUNTIFS($E:$E,$E13,$C:$C,">"&$C13)+COUNTIFS($E$8:E13,$E13,$C$8:C13,$C13)=1)) -> 1 | AE13: =IF($C13="","",TEXT($C13,"yyyy-mm")) -> 2026-03 | AF13: =IF(OR($E13="",$AE13=""),0,IF(COUNTIFS($E$8:E13,$E13,$AE$8:AE13,$AE13)=1,1,0)) -> 1 | AG13: =IF($E13="",0,IF(COUNTIF($E$8:E13,$E13)=1,1,0)) -> 1
A14: 7 | B14: محمد شوقى عايش ابو غبن | C14: 46110 | D14: {=IFERROR( LOOKUP(2, 1/((TRIM(IMS!$E$8:$E$4000)=TRIM(IMS!$E14))*(IMS!$C$8:$C$4000<IMS!$C14)), IMS!$C$8:$C$4000), "")} | E14: 803815695 | F14: 34347 | G14: 32 | H14: =IF(G14="","",IF(G14<=5,"0-5",IF(G14<=18,"6-18",IF(G14<=60,"19-60","+60")))) -> 19-60 | I14: Male | J14: =IF(OR(LOWER(TRIM(SUBSTITUTE(SUBSTITUTE($I14,CHAR(160)," "),_xludf.UNICHAR(8239)," ")))="male", LOWER(TRIM(SUBSTITUTE(SUBSTITUTE($I14,CHAR(160)," "),_xludf.UNICHAR(8239)," ")))="m", LOWER(TRIM(SUBSTITUTE(SUBSTITUTE($I14,CHAR(160)," "),_xludf.UNICHAR(8239)," ")))="males"), "male", IF(OR(LOWER(TRIM(SUBSTITUTE(SUBSTITUTE($I14,CHAR(160)," "),_xludf.UNICHAR(8239)," ")))="female", LOWER(TRIM(SUBSTITUTE(SUBSTITUTE($I14,CHAR(160)," "),_xludf.UNICHAR(8239)," ")))="f", LOWER(TRIM(SUBSTITUTE(SUBSTITUTE($I14,CHAR(160)," "),_xludf.UNICHAR(8239)," ")))="females"), "female", "")) -> #NAME? | K14: 537714853 | L14: Alnussirat | M14: Married | N14: No | P14: Displaced | Q14: FM- NCD | X14: =IF(E14="","",UPPER(LEFT($C$3,1)&"-"&LEFT($C$4,1)&"-"&TEXT(ROW(B7),"000")&"-"&TEXT(C14,"dd-mm"))) -> --007-29-03 | Y14: =TRIM(SUBSTITUTE(SUBSTITUTE(OFFSET($Q14,0,COLUMN()-COLUMN($AL$1)),CHAR(160)," "),_xludf.UNICHAR(8239)," ")) -> #NAME? | Z14: =TRIM(SUBSTITUTE(SUBSTITUTE(OFFSET($Q14,0,COLUMN()-COLUMN($AL$1)),CHAR(160)," "),_xludf.UNICHAR(8239)," ")) -> #NAME? | AA14: =TRIM(SUBSTITUTE(SUBSTITUTE(OFFSET($Q14,0,COLUMN()-COLUMN($AL$1)),CHAR(160)," "),_xludf.UNICHAR(8239)," ")) -> #NAME? | AB14: =TRIM(SUBSTITUTE(SUBSTITUTE(OFFSET($Q14,0,COLUMN()-COLUMN($AL$1)),CHAR(160)," "),_xludf.UNICHAR(8239)," ")) -> #NAME? | AC14: =TRIM(SUBSTITUTE(SUBSTITUTE(OFFSET($Q14,0,COLUMN()-COLUMN($AL$1)),CHAR(160)," "),_xludf.UNICHAR(8239)," ")) -> #NAME? | AD14: =IF($E14="",0,--(COUNTIFS($E:$E,$E14,$C:$C,">"&$C14)+COUNTIFS($E$8:E14,$E14,$C$8:C14,$C14)=1)) -> 1 | AE14: =IF($C14="","",TEXT($C14,"yyyy-mm")) -> 2026-03 | AF14: =IF(OR($E14="",$AE14=""),0,IF(COUNTIFS($E$8:E14,$E14,$AE$8:AE14,$AE14)=1,1,0)) -> 1 | AG14: =IF($E14="",0,IF(COUNTIF($E$8:E14,$E14)=1,1,0)) -> 1
A15: 8 | B15: يحى هشام صبحى ناصر | C15: 46110 | D15: {=IFERROR( LOOKUP(2, 1/((TRIM(IMS!$E$8:$E$4000)=TRIM(IMS!$E15))*(IMS!$C$8:$C$4000<IMS!$C15)), IMS!$C$8:$C$4000), "")} | E15: 445435407 | F15: 44864 | G15: 4 | H15: =IF(G15="","",IF(G15<=5,"0-5",IF(G15<=18,"6-18",IF(G15<=60,"19-60","+60")))) -> 0-5 | I15: Male | J15: =IF(OR(LOWER(TRIM(SUBSTITUTE(SUBSTITUTE($I15,CHAR(160)," "),_xludf.UNICHAR(8239)," ")))="male", LOWER(TRIM(SUBSTITUTE(SUBSTITUTE($I15,CHAR(160)," "),_xludf.UNICHAR(8239)," ")))="m", LOWER(TRIM(SUBSTITUTE(SUBSTITUTE($I15,CHAR(160)," "),_xludf.UNICHAR(8239)," ")))="males"), "male", IF(OR(LOWER(TRIM(SUBSTITUTE(SUBSTITUTE($I15,CHAR(160)," "),_xludf.UNICHAR(8239)," ")))="female", LOWER(TRIM(SUBSTITUTE(SUBSTITUTE($I15,CHAR(160)," "),_xludf.UNICHAR(8239)," ")))="f", LOWER(TRIM(SUBSTITUTE(SUBSTITUTE($I15,CHAR(160)," "),_xludf.UNICHAR(8239)," ")))="females"), "female", "")) -> #NAME? | K15: 597262253 | L15: Alnussirat | M15: N/A | N15: No | P15: Displaced | Q15: FM- NCD | X15: =IF(E15="","",UPPER(LEFT($C$3,1)&"-"&LEFT($C$4,1)&"-"&TEXT(ROW(B8),"000")&"-"&TEXT(C15,"dd-mm"))) -> --008-29-03 | Y15: =TRIM(SUBSTITUTE(SUBSTITUTE(OFFSET($Q15,0,COLUMN()-COLUMN($AL$1)),CHAR(160)," "),_xludf.UNICHAR(8239)," ")) -> #NAME? | Z15: =TRIM(SUBSTITUTE(SUBSTITUTE(OFFSET($Q15,0,COLUMN()-COLUMN($AL$1)),CHAR(160)," "),_xludf.UNICHAR(8239)," ")) -> #NAME? | AA15: =TRIM(SUBSTITUTE(SUBSTITUTE(OFFSET($Q15,0,COLUMN()-COLUMN($AL$1)),CHAR(160)," "),_xludf.UNICHAR(8239)," ")) -> #NAME? | AB15: =TRIM(SUBSTITUTE(SUBSTITUTE(OFFSET($Q15,0,COLUMN()-COLUMN($AL$1)),CHAR(160)," "),_xludf.UNICHAR(8239)," ")) -> #NAME? | AC15: =TRIM(SUBSTITUTE(SUBSTITUTE(OFFSET($Q15,0,COLUMN()-COLUMN($AL$1)),CHAR(160)," "),_xludf.UNICHAR(8239)," ")) -> #NAME? | AD15: =IF($E15="",0,--(COUNTIFS($E:$E,$E15,$C:$C,">"&$C15)+COUNTIFS($E$8:E15,$E15,$C$8:C15,$C15)=1)) -> 0 | AE15: =IF($C15="","",TEXT($C15,"yyyy-mm")) -> 2026-03 | AF15: =IF(OR($E15="",$AE15=""),0,IF(COUNTIFS($E$8:E15,$E15,$AE$8:AE15,$AE15)=1,1,0)) -> 1 | AG15: =IF($E15="",0,IF(COUNTIF($E$8:E15,$E15)=1,1,0)) -> 1
A16: 9 | B16: امير بشير خليل الزعانين | C16: 46110 | D16: {=IFERROR( LOOKUP(2, 1/((TRIM(IMS!$E$8:$E$4000)=TRIM(IMS!$E16))*(IMS!$C$8:$C$4000<IMS!$C16)), IMS!$C$8:$C$4000), "")} | E16: 604112938 | F16: 36625 | G16: 26 | H16: =IF(G16="","",IF(G16<=5,"0-5",IF(G16<=18,"6-18",IF(G16<=60,"19-60","+60")))) -> 19-60 | I16: Male | J16: =IF(OR(LOWER(TRIM(SUBSTITUTE(SUBSTITUTE($I16,CHAR(160)," "),_xludf.UNICHAR(8239)," ")))="male", LOWER(TRIM(SUBSTITUTE(SUBSTITUTE($I16,CHAR(160)," "),_xludf.UNICHAR(8239)," ")))="m", LOWER(TRIM(SUBSTITUTE(SUBSTITUTE($I16,CHAR(160)," "),_xludf.UNICHAR(8239)," ")))="males"), "male", IF(OR(LOWER(TRIM(SUBSTITUTE(SUBSTITUTE($I16,CHAR(160)," "),_xludf.UNICHAR(8239)," ")))="female", LOWER(TRIM(SUBSTITUTE(SUBSTITUTE($I16,CHAR(160)," "),_xludf.UNICHAR(8239)," ")))="f", LOWER(TRIM(SUBSTITUTE(SUBSTITUTE($I16,CHAR(160)," "),_xludf.UNICHAR(8239)," ")))="females"), "female", "")) -> #NAME? | K16: 597898553 | L16: Alnussirat | M16: Married | N16: No | P16: Displaced | Q16: FM- NCD | X16: =IF(E16="","",UPPER(LEFT($C$3,1)&"-"&LEFT($C$4,1)&"-"&TEXT(ROW(B9),"000")&"-"&TEXT(C16,"dd-mm"))) -> --009-29-03 | Y16: =TRIM(SUBSTITUTE(SUBSTITUTE(OFFSET($Q16,0,COLUMN()-COLUMN($AL$1)),CHAR(160)," "),_xludf.UNICHAR(8239)," ")) -> #NAME? | Z16: =TRIM(SUBSTITUTE(SUBSTITUTE(OFFSET($Q16,0,COLUMN()-COLUMN($AL$1)),CHAR(160)," "),_xludf.UNICHAR(8239)," ")) -> #NAME? | AA16: =TRIM(SUBSTITUTE(SUBSTITUTE(OFFSET($Q16,0,COLUMN()-COLUMN($AL$1)),CHAR(160)," "),_xludf.UNICHAR(8239)," ")) -> #NAME? | AB16: =TRIM(SUBSTITUTE(SUBSTITUTE(OFFSET($Q16,0,COLUMN()-COLUMN($AL$1)),CHAR(160)," "),_xludf.UNICHAR(8239)," ")) -> #NAME? | AC16: =TRIM(SUBSTITUTE(SUBSTITUTE(OFFSET($Q16,0,COLUMN()-COLUMN($AL$1)),CHAR(160)," "),_xludf.UNICHAR(8239)," ")) -> #NAME? | AD16: =IF($E16="",0,--(COUNTIFS($E:$E,$E16,$C:$C,">"&$C16)+COUNTIFS($E$8:E16,$E16,$C$8:C16,$C16)=1)) -> 1 | AE16: =IF($C16="","",TEXT($C16,"yyyy-mm")) -> 2026-03 | AF16: =IF(OR($E16="",$AE16=""),0,IF(COUNTIFS($E$8:E16,$E16,$AE$8:AE16,$AE16)=1,1,0)) -> 1 | AG16: =IF($E16="",0,IF(COUNTIF($E$8:E16,$E16)=1,1,0)) -> 1
A17: 10 | B17: عمر هاني سليمان ابو حمد | C17: 46110 | D17: {=IFERROR( LOOKUP(2, 1/((TRIM(IMS!$E$8:$E$4000)=TRIM(IMS!$E17))*(IMS!$C$8:$C$4000<IMS!$C17)), IMS!$C$8:$C$4000), "")} | E17: 438248288 | F17: 42964 | G17: 9 | H17: =IF(G17="","",IF(G17<=5,"0-5",IF(G17<=18,"6-18",IF(G17<=60,"19-60","+60")))) -> 6-18 | I17: Male | J17: =IF(OR(LOWER(TRIM(SUBSTITUTE(SUBSTITUTE($I17,CHAR(160)," "),_xludf.UNICHAR(8239)," ")))="male", LOWER(TRIM(SUBSTITUTE(SUBSTITUTE($I17,CHAR(160)," "),_xludf.UNICHAR(8239)," ")))="m", LOWER(TRIM(SUBSTITUTE(SUBSTITUTE($I17,CHAR(160)," "),_xludf.UNICHAR(8239)," ")))="males"), "male", IF(OR(LOWER(TRIM(SUBSTITUTE(SUBSTITUTE($I17,CHAR(160)," "),_xludf.UNICHAR(8239)," ")))="female", LOWER(TRIM(SUBSTITUTE(SUBSTITUTE($I17,CHAR(160)," "),_xludf.UNICHAR(8239)," ")))="f", LOWER(TRIM(SUBSTITUTE(SUBSTITUTE($I17,CHAR(160)," "),_xludf.UNICHAR(8239)," ")))="females"), "female", "")) -> #NAME? | K17: 599614343 | L17: Alnussirat | M17: N/A | N17: No | P17: Displaced | Q17: FM- CD | X17: =IF(E17="","",UPPER(LEFT($C$3,1)&"-"&LEFT($C$4,1)&"-"&TEXT(ROW(B10),"000")&"-"&TEXT(C17,"dd-mm"))) -> --010-29-03 | Y17: =TRIM(SUBSTITUTE(SUBSTITUTE(OFFSET($Q17,0,COLUMN()-COLUMN($AL$1)),CHAR(160)," "),_xludf.UNICHAR(8239)," ")) -> #NAME? | Z17: =TRIM(SUBSTITUTE(SUBSTITUTE(OFFSET($Q17,0,COLUMN()-COLUMN($AL$1)),CHAR(160)," "),_xludf.UNICHAR(8239)," ")) -> #NAME? | AA17: =TRIM(SUBSTITUTE(SUBSTITUTE(OFFSET($Q17,0,COLUMN()-COLUMN($AL$1)),CHAR(160)," "),_xludf.UNICHAR(8239)," ")) -> #NAME? | AB17: =TRIM(SUBSTITUTE(SUBSTITUTE(OFFSET($Q17,0,COLUMN()-COLUMN($AL$1)),CHAR(160)," "),_xludf.UNICHAR(8239)," ")) -> #NAME? | AC17: =TRIM(SUBSTITUTE(SUBSTITUTE(OFFSET($Q17,0,COLUMN()-COLUMN($AL$1)),CHAR(160)," "),_xludf.UNICHAR(8239)," ")) -> #NAME? | AD17: =IF($E17="",0,--(COUNTIFS($E:$E,$E17,$C:$C,">"&$C17)+COUNTIFS($E$8:E17,$E17,$C$8:C17,$C17)=1)) -> 1 | AE17: =IF($C17="","",TEXT($C17,"yyyy-mm")) -> 2026-03 | AF17: =IF(OR($E17="",$AE17=""),0,IF(COUNTIFS($E$8:E17,$E17,$AE$8:AE17,$AE17)=1,1,0)) -> 1 | AG17: =IF($E17="",0,IF(COUNTIF($E$8:E17,$E17)=1,1,0)) -> 1
A18: 11 | B18: ريحانه محمد احمد الزعانين | C18: 46110 | D18: {=IFERROR( LOOKUP(2, 1/((TRIM(IMS!$E$8:$E$4000)=TRIM(IMS!$E18))*(IMS!$C$8:$C$4000<IMS!$C18)), IMS!$C$8:$C$4000), "")} | E18: 801501354 | F18: 31767 | G18: 40 | H18: =IF(G18="","",IF(G18<=5,"0-5",IF(G18<=18,"6-18",IF(G18<=60,"19-60","+60")))) -> 19-60 | I18: FEMALE | J18: =IF(OR(LOWER(TRIM(SUBSTITUTE(SUBSTITUTE($I18,CHAR(160)," "),_xludf.UNICHAR(8239)," ")))="male", LOWER(TRIM(SUBSTITUTE(SUBSTITUTE($I18,CHAR(160)," "),_xludf.UNICHAR(8239)," ")))="m", LOWER(TRIM(SUBSTITUTE(SUBSTITUTE($I18,CHAR(160)," "),_xludf.UNICHAR(8239)," ")))="males"), "male", IF(OR(LOWER(TRIM(SUBSTITUTE(SUBSTITUTE($I18,CHAR(160)," "),_xludf.UNICHAR(8239)," ")))="female", LOWER(TRIM(SUBSTITUTE(SUBSTITUTE($I18,CHAR(160)," "),_xludf.UNICHAR(8239)," ")))="f", LOWER(TRIM(SUBSTITUTE(SUBSTITUTE($I18,CHAR(160)," "),_xludf.UNICHAR(8239)," ")))="females"), "female", "")) -> #NAME? | K18: 593621217 | L18: Alnussirat | M18: Married | N18: No | P18: Displaced | Q18: FM- NCD | X18: =IF(E18="","",UPPER(LEFT($C$3,1)&"-"&LEFT($C$4,1)&"-"&TEXT(ROW(B11),"000")&"-"&TEXT(C18,"dd-mm"))) -> --011-29-03 | Y18: =TRIM(SUBSTITUTE(SUBSTITUTE(OFFSET($Q18,0,COLUMN()-COLUMN($AL$1)),CHAR(160)," "),_xludf.UNICHAR(8239)," ")) -> #NAME? | Z18: =TRIM(SUBSTITUTE(SUBSTITUTE(OFFSET($Q18,0,COLUMN()-COLUMN($AL$1)),CHAR(160)," "),_xludf.UNICHAR(8239)," ")) -> #NAME? | AA18: =TRIM(SUBSTITUTE(SUBSTITUTE(OFFSET($Q18,0,COLUMN()-COLUMN($AL$1)),CHAR(160)," "),_xludf.UNICHAR(8239)," ")) -> #NAME? | AB18: =TRIM(SUBSTITUTE(SUBSTITUTE(OFFSET($Q18,0,COLUMN()-COLUMN($AL$1)),CHAR(160)," "),_xludf.UNICHAR(8239)," ")) -> #NAME? | AC18: =TRIM(SUBSTITUTE(SUBSTITUTE(OFFSET($Q18,0,COLUMN()-COLUMN($AL$1)),CHAR(160)," "),_xludf.UNICHAR(8239)," ")) -> #NAME? | AD18: =IF($E18="",0,--(COUNTIFS($E:$E,$E18,$C:$C,">"&$C18)+COUNTIFS($E$8:E18,$E18,$C$8:C18,$C18)=1)) -> 0 | AE18: =IF($C18="","",TEXT($C18,"yyyy-mm")) -> 2026-03 | AF18: =IF(OR($E18="",$AE18=""),0,IF(COUNTIFS($E$8:E18,$E18,$AE$8:AE18,$AE18)=1,1,0)) -> 1 | AG18: =IF($E18="",0,IF(COUNTIF($E$8:E18,$E18)=1,1,0)) -> 1
A19: 12 | B19: صفاء جمال محمد ابو الطيف | C19: 46110 | D19: {=IFERROR( LOOKUP(2, 1/((TRIM(IMS!$E$8:$E$4000)=TRIM(IMS!$E19))*(IMS!$C$8:$C$4000<IMS!$C19)), IMS!$C$8:$C$4000), "")} | E19: 800758761 | F19: 32267 | G19: 38 | H19: =IF(G19="","",IF(G19<=5,"0-5",IF(G19<=18,"6-18",IF(G19<=60,"19-60","+60")))) -> 19-60 | I19: FEMALE | J19: =IF(OR(LOWER(TRIM(SUBSTITUTE(SUBSTITUTE($I19,CHAR(160)," "),_xludf.UNICHAR(8239)," ")))="male", LOWER(TRIM(SUBSTITUTE(SUBSTITUTE($I19,CHAR(160)," "),_xludf.UNICHAR(8239)," ")))="m", LOWER(TRIM(SUBSTITUTE(SUBSTITUTE($I19,CHAR(160)," "),_xludf.UNICHAR(8239)," ")))="males"), "male", IF(OR(LOWER(TRIM(SUBSTITUTE(SUBSTITUTE($I19,CHAR(160)," "),_xludf.UNICHAR(8239)," ")))="female", LOWER(TRIM(SUBSTITUTE(SUBSTITUTE($I19,CHAR(160)," "),_xludf.UNICHAR(8239)," ")))="f", LOWER(TRIM(SUBSTITUTE(SUBSTITUTE($I19,CHAR(160)," "),_xludf.UNICHAR(8239)," ")))="females"), "female", "")) -> #NAME? | K19: 595339511 | L19: Alnussirat | M19: Married | N19: No | P19: Displaced | Q19: FM- NCD | X19: =IF(E19="","",UPPER(LEFT($C$3,1)&"-"&LEFT($C$4,1)&"-"&TEXT(ROW(B12),"000")&"-"&TEXT(C19,"dd-mm"))) -> --012-29-03 | Y19: =TRIM(SUBSTITUTE(SUBSTITUTE(OFFSET($Q19,0,COLUMN()-COLUMN($AL$1)),CHAR(160)," "),_xludf.UNICHAR(8239)," ")) -> #NAME? | Z19: =TRIM(SUBSTITUTE(SUBSTITUTE(OFFSET($Q19,0,COLUMN()-COLUMN($AL$1)),CHAR(160)," "),_xludf.UNICHAR(8239)," ")) -> #NAME? | AA19: =TRIM(SUBSTITUTE(SUBSTITUTE(OFFSET($Q19,0,COLUMN()-COLUMN($AL$1)),CHAR(160)," "),_xludf.UNICHAR(8239)," ")) -> #NAME? | AB19: =TRIM(SUBSTITUTE(SUBSTITUTE(OFFSET($Q19,0,COLUMN()-COLUMN($AL$1)),CHAR(160)," "),_xludf.UNICHAR(8239)," ")) -> #NAME? | AC19: =TRIM(SUBSTITUTE(SUBSTITUTE(OFFSET($Q19,0,COLUMN()-COLUMN($AL$1)),CHAR(160)," "),_xludf.UNICHAR(8239)," ")) -> #NAME? | AD19: =IF($E19="",0,--(COUNTIFS($E:$E,$E19,$C:$C,">"&$C19)+COUNTIFS($E$8:E19,$E19,$C$8:C19,$C19)=1)) -> 1 | AE19: =IF($C19="","",TEXT($C19,"yyyy-mm")) -> 2026-03 | AF19: =IF(OR($E19="",$AE19=""),0,IF(COUNTIFS($E$8:E19,$E19,$AE$8:AE19,$AE19)=1,1,0)) -> 1 | AG19: =IF($E19="",0,IF(COUNTIF($E$8:E19,$E19)=1,1,0)) -> 1
A20: 13 | B20: عمر حامد عمر ابو الطيف | C20: 46110 | D20: {=IFERROR( LOOKUP(2, 1/((TRIM(IMS!$E$8:$E$4000)=TRIM(IMS!$E20))*(IMS!$C$8:$C$4000<IMS!$C20)), IMS!$C$8:$C$4000), "")} | E20: 470829334 | F20: 44266 | G20: 5 m | H20: =IF(G20="","",IF(G20<=5,"0-5",IF(G20<=18,"6-18",IF(G20<=60,"19-60","+60")))) -> +60 | I20: Male | J20: =IF(OR(LOWER(TRIM(SUBSTITUTE(SUBSTITUTE($I20,CHAR(160)," "),_xludf.UNICHAR(8239)," ")))="male", LOWER(TRIM(SUBSTITUTE(SUBSTITUTE($I20,CHAR(160)," "),_xludf.UNICHAR(8239)," ")))="m", LOWER(TRIM(SUBSTITUTE(SUBSTITUTE($I20,CHAR(160)," "),_xludf.UNICHAR(8239)," ")))="males"), "male", IF(OR(LOWER(TRIM(SUBSTITUTE(SUBSTITUTE($I20,CHAR(160)," "),_xludf.UNICHAR(8239)," ")))="female", LOWER(TRIM(SUBSTITUTE(SUBSTITUTE($I20,CHAR(160)," "),_xludf.UNICHAR(8239)," ")))="f", LOWER(TRIM(SUBSTITUTE(SUBSTITUTE($I20,CHAR(160)," "),_xludf.UNICHAR(8239)," ")))="females"), "female", "")) -> #NAME? | K20: 595339511 | L20: Alnussirat | M20: N/A | N20: No | P20: Displaced | Q20: FM- CD | U20: Screening | X20: =IF(E20="","",UPPER(LEFT($C$3,1)&"-"&LEFT($C$4,1)&"-"&TEXT(ROW(B13),"000")&"-"&TEXT(C20,"dd-mm"))) -> --013-29-03 | Y20: =TRIM(SUBSTITUTE(SUBSTITUTE(OFFSET($Q20,0,COLUMN()-COLUMN($AL$1)),CHAR(160)," "),_xludf.UNICHAR(8239)," ")) -> #NAME? | Z20: =TRIM(SUBSTITUTE(SUBSTITUTE(OFFSET($Q20,0,COLUMN()-COLUMN($AL$1)),CHAR(160)," "),_xludf.UNICHAR(8239)," ")) -> #NAME? | AA20: =TRIM(SUBSTITUTE(SUBSTITUTE(OFFSET($Q20,0,COLUMN()-COLUMN($AL$1)),CHAR(160)," "),_xludf.UNICHAR(8239)," ")) -> #NAME? | AB20: =TRIM(SUBSTITUTE(SUBSTITUTE(OFFSET($Q20,0,COLUMN()-COLUMN($AL$1)),CHAR(160)," "),_xludf.UNICHAR(8239)," ")) -> #NAME? | AC20: =TRIM(SUBSTITUTE(SUBSTITUTE(OFFSET($Q20,0,COLUMN()-COLUMN($AL$1)),CHAR(160)," "),_xludf.UNICHAR(8239)," ")) -> #NAME? | AD20: =IF($E20="",0,--(COUNTIFS($E:$E,$E20,$C:$C,">"&$C20)+COUNTIFS($E$8:E20,$E20,$C$8:C20,$C20)=1)) -> 1 | AE20: =IF($C20="","",TEXT($C20,"yyyy-mm")) -> 2026-03 | AF20: =IF(OR($E20="",$AE20=""),0,IF(COUNTIFS($E$8:E20,$E20,$AE$8:AE20,$AE20)=1,1,0)) -> 1 | AG20: =IF($E20="",0,IF(COUNTIF($E$8:E20,$E20)=1,1,0)) -> 1
A21: 14 | B21: يوسف رياض محمد الغول | C21: 46110 | D21: {=IFERROR( LOOKUP(2, 1/((TRIM(IMS!$E$8:$E$4000)=TRIM(IMS!$E21))*(IMS!$C$8:$C$4000<IMS!$C21)), IMS!$C$8:$C$4000), "")} | E21: 803438365 | F21: 34240 | G21: 33 | H21: =IF(G21="","",IF(G21<=5,"0-5",IF(G21<=18,"6-18",IF(G21<=60,"19-60","+60")))) -> 19-60 | I21: Male | J21: =IF(OR(LOWER(TRIM(SUBSTITUTE(SUBSTITUTE($I21,CHAR(160)," "),_xludf.UNICHAR(8239)," ")))="male", LOWER(TRIM(SUBSTITUTE(SUBSTITUTE($I21,CHAR(160)," "),_xludf.UNICHAR(8239)," ")))="m", LOWER(TRIM(SUBSTITUTE(SUBSTITUTE($I21,CHAR(160)," "),_xludf.UNICHAR(8239)," ")))="males"), "male", IF(OR(LOWER(TRIM(SUBSTITUTE(SUBSTITUTE($I21,CHAR(160)," "),_xludf.UNICHAR(8239)," ")))="female", LOWER(TRIM(SUBSTITUTE(SUBSTITUTE($I21,CHAR(160)," "),_xludf.UNICHAR(8239)," ")))="f", LOWER(TRIM(SUBSTITUTE(SUBSTITUTE($I21,CHAR(160)," "),_xludf.UNICHAR(8239)," ")))="females"), "female", "")) -> #NAME? | K21: 592342178 | L21: Alnussirat | M21: Married | N21: No | P21: Displaced | Q21: FM- NCD | X21: =IF(E21="","",UPPER(LEFT($C$3,1)&"-"&LEFT($C$4,1)&"-"&TEXT(ROW(B14),"000")&"-"&TEXT(C21,"dd-mm"))) -> --014-29-03 | Y21: =TRIM(SUBSTITUTE(SUBSTITUTE(OFFSET($Q21,0,COLUMN()-COLUMN($AL$1)),CHAR(160)," "),_xludf.UNICHAR(8239)," ")) -> #NAME? | Z21: =TRIM(SUBSTITUTE(SUBSTITUTE(OFFSET($Q21,0,COLUMN()-COLUMN($AL$1)),CHAR(160)," "),_xludf.UNICHAR(8239)," ")) -> #NAME? | AA21: =TRIM(SUBSTITUTE(SUBSTITUTE(OFFSET($Q21,0,COLUMN()-COLUMN($AL$1)),CHAR(160)," "),_xludf.UNICHAR(8239)," ")) -> #NAME? | AB21: =TRIM(SUBSTITUTE(SUBSTITUTE(OFFSET($Q21,0,COLUMN()-COLUMN($AL$1)),CHAR(160)," "),_xludf.UNICHAR(8239)," ")) -> #NAME? | AC21: =TRIM(SUBSTITUTE(SUBSTITUTE(OFFSET($Q21,0,COLUMN()-COLUMN($AL$1)),CHAR(160)," "),_xludf.UNICHAR(8239)," ")) -> #NAME? | AD21: =IF($E21="",0,--(COUNTIFS($E:$E,$E21,$C:$C,">"&$C21)+COUNTIFS($E$8:E21,$E21,$C$8:C21,$C21)=1)) -> 1 | AE21: =IF($C21="","",TEXT($C21,"yyyy-mm")) -> 2026-03 | AF21: =IF(OR($E21="",$AE21=""),0,IF(COUNTIFS($E$8:E21,$E21,$AE$8:AE21,$AE21)=1,1,0)) -> 1 | AG21: =IF($E21="",0,IF(COUNTIF($E$8:E21,$E21)=1,1,0)) -> 1
A22: 15 | B22: تحرير اكرام اسماعيل حسين | C22: 46110 | D22: {=IFERROR( LOOKUP(2, 1/((TRIM(IMS!$E$8:$E$4000)=TRIM(IMS!$E22))*(IMS!$C$8:$C$4000<IMS!$C22)), IMS!$C$8:$C$4000), "")} | E22: 802526095 | F22: 33425 | G22: 35 | H22: =IF(G22="","",IF(G22<=5,"0-5",IF(G22<=18,"6-18",IF(G22<=60,"19-60","+60")))) -> 19-60 | I22: FEMALE | J22: =IF(OR(LOWER(TRIM(SUBSTITUTE(SUBSTITUTE($I22,CHAR(160)," "),_xludf.UNICHAR(8239)," ")))="male", LOWER(TRIM(SUBSTITUTE(SUBSTITUTE($I22,CHAR(160)," "),_xludf.UNICHAR(8239)," ")))="m", LOWER(TRIM(SUBSTITUTE(SUBSTITUTE($I22,CHAR(160)," "),_xludf.UNICHAR(8239)," ")))="males"), "male", IF(OR(LOWER(TRIM(SUBSTITUTE(SUBSTITUTE($I22,CHAR(160)," "),_xludf.UNICHAR(8239)," ")))="female", LOWER(TRIM(SUBSTITUTE(SUBSTITUTE($I22,CHAR(160)," "),_xludf.UNICHAR(8239)," ")))="f", LOWER(TRIM(SUBSTITUTE(SUBSTITUTE($I22,CHAR(160)," "),_xludf.UNICHAR(8239)," ")))="females"), "female", "")) -> #NAME? | K22: 592247503 | L22: Alnussirat | M22: Married | N22: No | P22: Displaced | Q22: FM- CD | X22: =IF(E22="","",UPPER(LEFT($C$3,1)&"-"&LEFT($C$4,1)&"-"&TEXT(ROW(B15),"000")&"-"&TEXT(C22,"dd-mm"))) -> --015-29-03 | Y22: =TRIM(SUBSTITUTE(SUBSTITUTE(OFFSET($Q22,0,COLUMN()-COLUMN($AL$1)),CHAR(160)," "),_xludf.UNICHAR(8239)," ")) -> #NAME? | Z22: =TRIM(SUBSTITUTE(SUBSTITUTE(OFFSET($Q22,0,COLUMN()-COLUMN($AL$1)),CHAR(160)," "),_xludf.UNICHAR(8239)," ")) -> #NAME? | AA22: =TRIM(SUBSTITUTE(SUBSTITUTE(OFFSET($Q22,0,COLUMN()-COLUMN($AL$1)),CHAR(160)," "),_xludf.UNICHAR(8239)," ")) -> #NAME? | AB22: =TRIM(SUBSTITUTE(SUBSTITUTE(OFFSET($Q22,0,COLUMN()-COLUMN($AL$1)),CHAR(160)," "),_xludf.UNICHAR(8239)," ")) -> #NAME? | AC22: =TRIM(SUBSTITUTE(SUBSTITUTE(OFFSET($Q22,0,COLUMN()-COLUMN($AL$1)),CHAR(160)," "),_xludf.UNICHAR(8239)," ")) -> #NAME? | AD22: =IF($E22="",0,--(COUNTIFS($E:$E,$E22,$C:$C,">"&$C22)+COUNTIFS($E$8:E22,$E22,$C$8:C22,$C22)=1)) -> 0 | AE22: =IF($C22="","",TEXT($C22,"yyyy-mm")) -> 2026-03 | AF22: =IF(OR($E22="",$AE22=""),0,IF(COUNTIFS($E$8:E22,$E22,$AE$8:AE22,$AE22)=1,1,0)) -> 1 | AG22: =IF($E22="",0,IF(COUNTIF($E$8:E22,$E22)=1,1,0)) -> 1
A23: 16 | B23: حنان جمال قنديل عوض | C23: 46110 | D23: {=IFERROR( LOOKUP(2, 1/((TRIM(IMS!$E$8:$E$4000)=TRIM(IMS!$E23))*(IMS!$C$8:$C$4000<IMS!$C23)), IMS!$C$8:$C$4000), "")} | E23: 802111419 | F23: 32191 | G23: 38 | H23: =IF(G23="","",IF(G23<=5,"0-5",IF(G23<=18,"6-18",IF(G23<=60,"19-60","+60")))) -> 19-60 | I23: FEMALE | J23: =IF(OR(LOWER(TRIM(SUBSTITUTE(SUBSTITUTE($I23,CHAR(160)," "),_xludf.UNICHAR(8239)," ")))="male", LOWER(TRIM(SUBSTITUTE(SUBSTITUTE($I23,CHAR(160)," "),_xludf.UNICHAR(8239)," ")))="m", LOWER(TRIM(SUBSTITUTE(SUBSTITUTE($I23,CHAR(160)," "),_xludf.UNICHAR(8239)," ")))="males"), "male", IF(OR(LOWER(TRIM(SUBSTITUTE(SUBSTITUTE($I23,CHAR(160)," "),_xludf.UNICHAR(8239)," ")))="female", LOWER(TRIM(SUBSTITUTE(SUBSTITUTE($I23,CHAR(160)," "),_xludf.UNICHAR(8239)," ")))="f", LOWER(TRIM(SUBSTITUTE(SUBSTITUTE($I23,CHAR(160)," "),_xludf.UNICHAR(8239)," ")))="females"), "female", "")) -> #NAME? | K23: 598985336 | L23: Alnussirat | M23: Married | N23: No | P23: Displaced | Q23: FM- CD | X23: =IF(E23="","",UPPER(LEFT($C$3,1)&"-"&LEFT($C$4,1)&"-"&TEXT(ROW(B16),"000")&"-"&TEXT(C23,"dd-mm"))) -> --016-29-03 | Y23: =TRIM(SUBSTITUTE(SUBSTITUTE(OFFSET($Q23,0,COLUMN()-COLUMN($AL$1)),CHAR(160)," "),_xludf.UNICHAR(8239)," ")) -> #NAME? | Z23: =TRIM(SUBSTITUTE(SUBSTITUTE(OFFSET($Q23,0,COLUMN()-COLUMN($AL$1)),CHAR(160)," "),_xludf.UNICHAR(8239)," ")) -> #NAME? | AA23: =TRIM(SUBSTITUTE(SUBSTITUTE(OFFSET($Q23,0,COLUMN()-COLUMN($AL$1)),CHAR(160)," "),_xludf.UNICHAR(8239)," ")) -> #NAME? | AB23: =TRIM(SUBSTITUTE(SUBSTITUTE(OFFSET($Q23,0,COLUMN()-COLUMN($AL$1)),CHAR(160)," "),_xludf.UNICHAR(8239)," ")) -> #NAME? | AC23: =TRIM(SUBSTITUTE(SUBSTITUTE(OFFSET($Q23,0,COLUMN()-COLUMN($AL$1)),CHAR(160)," "),_xludf.UNICHAR(8239)," ")) -> #NAME? | AD23: =IF($E23="",0,--(COUNTIFS($E:$E,$E23,$C:$C,">"&$C23)+COUNTIFS($E$8:E23,$E23,$C$8:C23,$C23)=1)) -> 0 | AE23: =IF($C23="","",TEXT($C23,"yyyy-mm")) -> 2026-03 | AF23: =IF(OR($E23="",$AE23=""),0,IF(COUNTIFS($E$8:E23,$E23,$AE$8:AE23,$AE23)=1,1,0)) -> 1 | AG23: =IF($E23="",0,IF(COUNTIF($E$8:E23,$E23)=1,1,0)) -> 1
A24: 17 | B24: مها تحسين عبدالفتاح عودة | C24: 46110 | D24: {=IFERROR( LOOKUP(2, 1/((TRIM(IMS!$E$8:$E$4000)=TRIM(IMS!$E24))*(IMS!$C$8:$C$4000<IMS!$C24)), IMS!$C$8:$C$4000), "")} | E24: 802157248 | F24: 32456 | G24: 38 | H24: =IF(G24="","",IF(G24<=5,"0-5",IF(G24<=18,"6-18",IF(G24<=60,"19-60","+60")))) -> 19-60 | I24: FEMALE | J24: =IF(OR(LOWER(TRIM(SUBSTITUTE(SUBSTITUTE($I24,CHAR(160)," "),_xludf.UNICHAR(8239)," ")))="male", LOWER(TRIM(SUBSTITUTE(SUBSTITUTE($I24,CHAR(160)," "),_xludf.UNICHAR(8239)," ")))="m", LOWER(TRIM(SUBSTITUTE(SUBSTITUTE($I24,CHAR(160)," "),_xludf.UNICHAR(8239)," ")))="males"), "male", IF(OR(LOWER(TRIM(SUBSTITUTE(SUBSTITUTE($I24,CHAR(160)," "),_xludf.UNICHAR(8239)," ")))="female", LOWER(TRIM(SUBSTITUTE(SUBSTITUTE($I24,CHAR(160)," "),_xludf.UNICHAR(8239)," ")))="f", LOWER(TRIM(SUBSTITUTE(SUBSTITUTE($I24,CHAR(160)," "),_xludf.UNICHAR(8239)," ")))="females"), "female", "")) -> #NAME? | K24: 597239384 | L24: Alnussirat | M24: Married | N24: No | P24: Displaced | R24: ANC | X24: =IF(E24="","",UPPER(LEFT($C$3,1)&"-"&LEFT($C$4,1)&"-"&TEXT(ROW(B17),"000")&"-"&TEXT(C24,"dd-mm"))) -> --017-29-03 | Y24: =TRIM(SUBSTITUTE(SUBSTITUTE(OFFSET($Q24,0,COLUMN()-COLUMN($AL$1)),CHAR(160)," "),_xludf.UNICHAR(8239)," ")) -> #NAME? | Z24: =TRIM(SUBSTITUTE(SUBSTITUTE(OFFSET($Q24,0,COLUMN()-COLUMN($AL$1)),CHAR(160)," "),_xludf.UNICHAR(8239)," ")) -> #NAME? | AA24: =TRIM(SUBSTITUTE(SUBSTITUTE(OFFSET($Q24,0,COLUMN()-COLUMN($AL$1)),CHAR(160)," "),_xludf.UNICHAR(8239)," ")) -> #NAME? | AB24: =TRIM(SUBSTITUTE(SUBSTITUTE(OFFSET($Q24,0,COLUMN()-COLUMN($AL$1)),CHAR(160)," "),_xludf.UNICHAR(8239)," ")) -> #NAME? | AC24: =TRIM(SUBSTITUTE(SUBSTITUTE(OFFSET($Q24,0,COLUMN()-COLUMN($AL$1)),CHAR(160)," "),_xludf.UNICHAR(8239)," ")) -> #NAME? | AD24: =IF($E24="",0,--(COUNTIFS($E:$E,$E24,$C:$C,">"&$C24)+COUNTIFS($E$8:E24,$E24,$C$8:C24,$C24)=1)) -> 0 | AE24: =IF($C24="","",TEXT($C24,"yyyy-mm")) -> 2026-03 | AF24: =IF(OR($E24="",$AE24=""),0,IF(COUNTIFS($E$8:E24,$E24,$AE$8:AE24,$AE24)=1,1,0)) -> 1 | AG24: =IF($E24="",0,IF(COUNTIF($E$8:E24,$E24)=1,1,0)) -> 1
A25: 18 | B25: عبدالله اسماعيل حسين الزعانين | C25: 46110 | D25: {=IFERROR( LOOKUP(2, 1/((TRIM(IMS!$E$8:$E$4000)=TRIM(IMS!$E25))*(IMS!$C$8:$C$4000<IMS!$C25)), IMS!$C$8:$C$4000), "")} | E25: 803336981 | F25: 34359 | G25: 32 | H25: =IF(G25="","",IF(G25<=5,"0-5",IF(G25<=18,"6-18",IF(G25<=60,"19-60","+60")))) -> 19-60 | I25: Male | J25: =IF(OR(LOWER(TRIM(SUBSTITUTE(SUBSTITUTE($I25,CHAR(160)," "),_xludf.UNICHAR(8239)," ")))="male", LOWER(TRIM(SUBSTITUTE(SUBSTITUTE($I25,CHAR(160)," "),_xludf.UNICHAR(8239)," ")))="m", LOWER(TRIM(SUBSTITUTE(SUBSTITUTE($I25,CHAR(160)," "),_xludf.UNICHAR(8239)," ")))="males"), "male", IF(OR(LOWER(TRIM(SUBSTITUTE(SUBSTITUTE($I25,CHAR(160)," "),_xludf.UNICHAR(8239)," ")))="female", LOWER(TRIM(SUBSTITUTE(SUBSTITUTE($I25,CHAR(160)," "),_xludf.UNICHAR(8239)," ")))="f", LOWER(TRIM(SUBSTITUTE(SUBSTITUTE($I25,CHAR(160)," "),_xludf.UNICHAR(8239)," ")))="females"), "female", "")) -> #NAME? | K25: 598705037 | L25: Alnussirat | M25: Married | N25: No | P25: Displaced | Q25: FM- CD | S25: Dressing | X25: =IF(E25="","",UPPER(LEFT($C$3,1)&"-"&LEFT($C$4,1)&"-"&TEXT(ROW(B18),"000")&"-"&TEXT(C25,"dd-mm"))) -> --018-29-03 | Y25: =TRIM(SUBSTITUTE(SUBSTITUTE(OFFSET($Q25,0,COLUMN()-COLUMN($AL$1)),CHAR(160)," "),_xludf.UNICHAR(8239)," ")) -> #NAME? | Z25: =TRIM(SUBSTITUTE(SUBSTITUTE(OFFSET($Q25,0,COLUMN()-COLUMN($AL$1)),CHAR(160)," "),_xludf.UNICHAR(8239)," ")) -> #NAME? | AA25: =TRIM(SUBSTITUTE(SUBSTITUTE(OFFSET($Q25,0,COLUMN()-COLUMN($AL$1)),CHAR(160)," "),_xludf.UNICHAR(8239)," ")) -> #NAME? | AB25: =TRIM(SUBSTITUTE(SUBSTITUTE(OFFSET($Q25,0,COLUMN()-COLUMN($AL$1)),CHAR(160)," "),_xludf.UNICHAR(8239)," ")) -> #NAME? | AC25: =TRIM(SUBSTITUTE(SUBSTITUTE(OFFSET($Q25,0,COLUMN()-COLUMN($AL$1)),CHAR(160)," "),_xludf.UNICHAR(8239)," ")) -> #NAME? | AD25: =IF($E25="",0,--(COUNTIFS($E:$E,$E25,$C:$C,">"&$C25)+COUNTIFS($E$8:E25,$E25,$C$8:C25,$C25)=1)) -> 0 | AE25: =IF($C25="","",TEXT($C25,"yyyy-mm")) -> 2026-03 | AF25: =IF(OR($E25="",$AE25=""),0,IF(COUNTIFS($E$8:E25,$E25,$AE$8:AE25,$AE25)=1,1,0)) -> 1 | AG25: =IF($E25="",0,IF(COUNTIF($E$8:E25,$E25)=1,1,0)) -> 1
A26: 19 | B26: رضا ابراهيم حسنى ابو دقن | C26: 46110 | D26: {=IFERROR( LOOKUP(2, 1/((TRIM(IMS!$E$8:$E$4000)=TRIM(IMS!$E26))*(IMS!$C$8:$C$4000<IMS!$C26)), IMS!$C$8:$C$4000), "")} | E26: 906715354 | F26: 30481 | G26: 43 | H26: =IF(G26="","",IF(G26<=5,"0-5",IF(G26<=18,"6-18",IF(G26<=60,"19-60","+60")))) -> 19-60 | I26: FEMALE | J26: =IF(OR(LOWER(TRIM(SUBSTITUTE(SUBSTITUTE($I26,CHAR(160)," "),_xludf.UNICHAR(8239)," ")))="male", LOWER(TRIM(SUBSTITUTE(SUBSTITUTE($I26,CHAR(160)," "),_xludf.UNICHAR(8239)," ")))="m", LOWER(TRIM(SUBSTITUTE(SUBSTITUTE($I26,CHAR(160)," "),_xludf.UNICHAR(8239)," ")))="males"), "male", IF(OR(LOWER(TRIM(SUBSTITUTE(SUBSTITUTE($I26,CHAR(160)," "),_xludf.UNICHAR(8239)," ")))="female", LOWER(TRIM(SUBSTITUTE(SUBSTITUTE($I26,CHAR(160)," "),_xludf.UNICHAR(8239)," ")))="f", LOWER(TRIM(SUBSTITUTE(SUBSTITUTE($I26,CHAR(160)," "),_xludf.UNICHAR(8239)," ")))="females"), "female", "")) -> #NAME? | K26: 592342881 | L26: Alnussirat | M26: Married | N26: No | P26: Displaced | R26: GYN | X26: =IF(E26="","",UPPER(LEFT($C$3,1)&"-"&LEFT($C$4,1)&"-"&TEXT(ROW(B19),"000")&"-"&TEXT(C26,"dd-mm"))) -> --019-29-03 | Y26: =TRIM(SUBSTITUTE(SUBSTITUTE(OFFSET($Q26,0,COLUMN()-COLUMN($AL$1)),CHAR(160)," "),_xludf.UNICHAR(8239)," ")) -> #NAME? | Z26: =TRIM(SUBSTITUTE(SUBSTITUTE(OFFSET($Q26,0,COLUMN()-COLUMN($AL$1)),CHAR(160)," "),_xludf.UNICHAR(8239)," ")) -> #NAME? | AA26: =TRIM(SUBSTITUTE(SUBSTITUTE(OFFSET($Q26,0,COLUMN()-COLUMN($AL$1)),CHAR(160)," "),_xludf.UNICHAR(8239)," ")) -> #NAME? | AB26: =TRIM(SUBSTITUTE(SUBSTITUTE(OFFSET($Q26,0,COLUMN()-COLUMN($AL$1)),CHAR(160)," "),_xludf.UNICHAR(8239)," ")) -> #NAME? | AC26: =TRIM(SUBSTITUTE(SUBSTITUTE(OFFSET($Q26,0,COLUMN()-COLUMN($AL$1)),CHAR(160)," "),_xludf.UNICHAR(8239)," ")) -> #NAME? | AD26: =IF($E26="",0,--(COUNTIFS($E:$E,$E26,$C:$C,">"&$C26)+COUNTIFS($E$8:E26,$E26,$C$8:C26,$C26)=1)) -> 1 | AE26: =IF($C26="","",TEXT($C26,"yyyy-mm")) -> 2026-03 | AF26: =IF(OR($E26="",$AE26=""),0,IF(COUNTIFS($E$8:E26,$E26,$AE$8:AE26,$AE26)=1,1,0)) -> 1 | AG26: =IF($E26="",0,IF(COUNTIF($E$8:E26,$E26)=1,1,0)) -> 1
A27: 20 | B27: عايدة اكرم اسماعيل صيام | C27: 46110 | D27: {=IFERROR( LOOKUP(2, 1/((TRIM(IMS!$E$8:$E$4000)=TRIM(IMS!$E27))*(IMS!$C$8:$C$4000<IMS!$C27)), IMS!$C$8:$C$4000), "")} | E27: 801420449 | F27: 31627 | G27: 40 | H27: =IF(G27="","",IF(G27<=5,"0-5",IF(G27<=18,"6-18",IF(G27<=60,"19-60","+60")))) -> 19-60 | I27: FEMALE | J27: =IF(OR(LOWER(TRIM(SUBSTITUTE(SUBSTITUTE($I27,CHAR(160)," "),_xludf.UNICHAR(8239)," ")))="male", LOWER(TRIM(SUBSTITUTE(SUBSTITUTE($I27,CHAR(160)," "),_xludf.UNICHAR(8239)," ")))="m", LOWER(TRIM(SUBSTITUTE(SUBSTITUTE($I27,CHAR(160)," "),_xludf.UNICHAR(8239)," ")))="males"), "male", IF(OR(LOWER(TRIM(SUBSTITUTE(SUBSTITUTE($I27,CHAR(160)," "),_xludf.UNICHAR(8239)," ")))="female", LOWER(TRIM(SUBSTITUTE(SUBSTITUTE($I27,CHAR(160)," "),_xludf.UNICHAR(8239)," ")))="f", LOWER(TRIM(SUBSTITUTE(SUBSTITUTE($I27,CHAR(160)," "),_xludf.UNICHAR(8239)," ")))="females"), "female", "")) -> #NAME? | K27: 599850670 | L27: Alnussirat | M27: Married | N27: No | P27: Displaced | Q27: FM- CD | X27: =IF(E27="","",UPPER(LEFT($C$3,1)&"-"&LEFT($C$4,1)&"-"&TEXT(ROW(B20),"000")&"-"&TEXT(C27,"dd-mm"))) -> --020-29-03 | Y27: =TRIM(SUBSTITUTE(SUBSTITUTE(OFFSET($Q27,0,COLUMN()-COLUMN($AL$1)),CHAR(160)," "),_xludf.UNICHAR(8239)," ")) -> #NAME? | Z27: =TRIM(SUBSTITUTE(SUBSTITUTE(OFFSET($Q27,0,COLUMN()-COLUMN($AL$1)),CHAR(160)," "),_xludf.UNICHAR(8239)," ")) -> #NAME? | AA27: =TRIM(SUBSTITUTE(SUBSTITUTE(OFFSET($Q27,0,COLUMN()-COLUMN($AL$1)),CHAR(160)," "),_xludf.UNICHAR(8239)," ")) -> #NAME? | AB27: =TRIM(SUBSTITUTE(SUBSTITUTE(OFFSET($Q27,0,COLUMN()-COLUMN($AL$1)),CHAR(160)," "),_xludf.UNICHAR(8239)," ")) -> #NAME? | AC27: =TRIM(SUBSTITUTE(SUBSTITUTE(OFFSET($Q27,0,COLUMN()-COLUMN($AL$1)),CHAR(160)," "),_xludf.UNICHAR(8239)," ")) -> #NAME? | AD27: =IF($E27="",0,--(COUNTIFS($E:$E,$E27,$C:$C,">"&$C27)+COUNTIFS($E$8:E27,$E27,$C$8:C27,$C27)=1)) -> 0 | AE27: =IF($C27="","",TEXT($C27,"yyyy-mm")) -> 2026-03 | AF27: =IF(OR($E27="",$AE27=""),0,IF(COUNTIFS($E$8:E27,$E27,$AE$8:AE27,$AE27)=1,1,0)) -> 1 | AG27: =IF($E27="",0,IF(COUNTIF($E$8:E27,$E27)=1,1,0)) -> 1
A28: 21 | B28: وعد راىد سعد صيام | C28: 46110 | D28: {=IFERROR( LOOKUP(2, 1/((TRIM(IMS!$E$8:$E$4000)=TRIM(IMS!$E28))*(IMS!$C$8:$C$4000<IMS!$C28)), IMS!$C$8:$C$4000), "")} | E28: 407114826 | F28: 39201 | G28: 19 | H28: =IF(G28="","",IF(G28<=5,"0-5",IF(G28<=18,"6-18",IF(G28<=60,"19-60","+60")))) -> 19-60 | I28: FEMALE | J28: =IF(OR(LOWER(TRIM(SUBSTITUTE(SUBSTITUTE($I28,CHAR(160)," "),_xludf.UNICHAR(8239)," ")))="male", LOWER(TRIM(SUBSTITUTE(SUBSTITUTE($I28,CHAR(160)," "),_xludf.UNICHAR(8239)," ")))="m", LOWER(TRIM(SUBSTITUTE(SUBSTITUTE($I28,CHAR(160)," "),_xludf.UNICHAR(8239)," ")))="males"), "male", IF(OR(LOWER(TRIM(SUBSTITUTE(SUBSTITUTE($I28,CHAR(160)," "),_xludf.UNICHAR(8239)," ")))="female", LOWER(TRIM(SUBSTITUTE(SUBSTITUTE($I28,CHAR(160)," "),_xludf.UNICHAR(8239)," ")))="f", LOWER(TRIM(SUBSTITUTE(SUBSTITUTE($I28,CHAR(160)," "),_xludf.UNICHAR(8239)," ")))="females"), "female", "")) -> #NAME? | K28: 598605330 | L28: Alnussirat | M28: Widowed | N28: No | P28: Displaced | Q28: FM- CD | X28: =IF(E28="","",UPPER(LEFT($C$3,1)&"-"&LEFT($C$4,1)&"-"&TEXT(ROW(B21),"000")&"-"&TEXT(C28,"dd-mm"))) -> --021-29-03 | Y28: =TRIM(SUBSTITUTE(SUBSTITUTE(OFFSET($Q28,0,COLUMN()-COLUMN($AL$1)),CHAR(160)," "),_xludf.UNICHAR(8239)," ")) -> #NAME? | Z28: =TRIM(SUBSTITUTE(SUBSTITUTE(OFFSET($Q28,0,COLUMN()-COLUMN($AL$1)),CHAR(160)," "),_xludf.UNICHAR(8239)," ")) -> #NAME? | AA28: =TRIM(SUBSTITUTE(SUBSTITUTE(OFFSET($Q28,0,COLUMN()-COLUMN($AL$1)),CHAR(160)," "),_xludf.UNICHAR(8239)," ")) -> #NAME? | AB28: =TRIM(SUBSTITUTE(SUBSTITUTE(OFFSET($Q28,0,COLUMN()-COLUMN($AL$1)),CHAR(160)," "),_xludf.UNICHAR(8239)," ")) -> #NAME? | AC28: =TRIM(SUBSTITUTE(SUBSTITUTE(OFFSET($Q28,0,COLUMN()-COLUMN($AL$1)),CHAR(160)," "),_xludf.UNICHAR(8239)," ")) -> #NAME? | AD28: =IF($E28="",0,--(COUNTIFS($E:$E,$E28,$C:$C,">"&$C28)+COUNTIFS($E$8:E28,$E28,$C$8:C28,$C28)=1)) -> 1 | AE28: =IF($C28="","",TEXT($C28,"yyyy-mm")) -> 2026-03 | AF28: =IF(OR($E28="",$AE28=""),0,IF(COUNTIFS($E$8:E28,$E28,$AE$8:AE28,$AE28)=1,1,0)) -> 1 | AG28: =IF($E28="",0,IF(COUNTIF($E$8:E28,$E28)=1,1,0)) -> 1
A29: 22 | B29: نرمين واىل يوسف الاعرج | C29: 46110 | D29: {=IFERROR( LOOKUP(2, 1/((TRIM(IMS!$E$8:$E$4000)=TRIM(IMS!$E29))*(IMS!$C$8:$C$4000<IMS!$C29)), IMS!$C$8:$C$4000), "")} | E29: 403670334 | F29: 34254 | G29: 33 | H29: =IF(G29="","",IF(G29<=5,"0-5",IF(G29<=18,"6-18",IF(G29<=60,"19-60","+60")))) -> 19-60 | I29: FEMALE | J29: =IF(OR(LOWER(TRIM(SUBSTITUTE(SUBSTITUTE($I29,CHAR(160)," "),_xludf.UNICHAR(8239)," ")))="male", LOWER(TRIM(SUBSTITUTE(SUBSTITUTE($I29,CHAR(160)," "),_xludf.UNICHAR(8239)," ")))="m", LOWER(TRIM(SUBSTITUTE(SUBSTITUTE($I29,CHAR(160)," "),_xludf.UNICHAR(8239)," ")))="males"), "male", IF(OR(LOWER(TRIM(SUBSTITUTE(SUBSTITUTE($I29,CHAR(160)," "),_xludf.UNICHAR(8239)," ")))="female", LOWER(TRIM(SUBSTITUTE(SUBSTITUTE($I29,CHAR(160)," "),_xludf.UNICHAR(8239)," ")))="f", LOWER(TRIM(SUBSTITUTE(SUBSTITUTE($I29,CHAR(160)," "),_xludf.UNICHAR(8239)," ")))="females"), "female", "")) -> #NAME? | K29: 595756106 | L29: Alnussirat | M29: Married | N29: No | P29: Displaced | R29: GYN | X29: =IF(E29="","",UPPER(LEFT($C$3,1)&"-"&LEFT($C$4,1)&"-"&TEXT(ROW(B22),"000")&"-"&TEXT(C29,"dd-mm"))) -> --022-29-03 | Y29: =TRIM(SUBSTITUTE(SUBSTITUTE(OFFSET($Q29,0,COLUMN()-COLUMN($AL$1)),CHAR(160)," "),_xludf.UNICHAR(8239)," ")) -> #NAME? | Z29: =TRIM(SUBSTITUTE(SUBSTITUTE(OFFSET($Q29,0,COLUMN()-COLUMN($AL$1)),CHAR(160)," "),_xludf.UNICHAR(8239)," ")) -> #NAME? | AA29: =TRIM(SUBSTITUTE(SUBSTITUTE(OFFSET($Q29,0,COLUMN()-COLUMN($AL$1)),CHAR(160)," "),_xludf.UNICHAR(8239)," ")) -> #NAME? | AB29: =TRIM(SUBSTITUTE(SUBSTITUTE(OFFSET($Q29,0,COLUMN()-COLUMN($AL$1)),CHAR(160)," "),_xludf.UNICHAR(8239)," ")) -> #NAME? | AC29: =TRIM(SUBSTITUTE(SUBSTITUTE(OFFSET($Q29,0,COLUMN()-COLUMN($AL$1)),CHAR(160)," "),_xludf.UNICHAR(8239)," ")) -> #NAME? | AD29: =IF($E29="",0,--(COUNTIFS($E:$E,$E29,$C:$C,">"&$C29)+COUNTIFS($E$8:E29,$E29,$C$8:C29,$C29)=1)) -> 0 | AE29: =IF($C29="","",TEXT($C29,"yyyy-mm")) -> 2026-03 | AF29: =IF(OR($E29="",$AE29=""),0,IF(COUNTIFS($E$8:E29,$E29,$AE$8:AE29,$AE29)=1,1,0)) -> 1 | AG29: =IF($E29="",0,IF(COUNTIF($E$8:E29,$E29)=1,1,0)) -> 1
A30: 23 | B30: شهد راىد سعد صيام | C30: 46110 | D30: {=IFERROR( LOOKUP(2, 1/((TRIM(IMS!$E$8:$E$4000)=TRIM(IMS!$E30))*(IMS!$C$8:$C$4000<IMS!$C30)), IMS!$C$8:$C$4000), "")} | E30: 421063199 | F30: 38418 | G30: 21 | H30: =IF(G30="","",IF(G30<=5,"0-5",IF(G30<=18,"6-18",IF(G30<=60,"19-60","+60")))) -> 19-60 | I30: FEMALE | J30: =IF(OR(LOWER(TRIM(SUBSTITUTE(SUBSTITUTE($I30,CHAR(160)," "),_xludf.UNICHAR(8239)," ")))="male", LOWER(TRIM(SUBSTITUTE(SUBSTITUTE($I30,CHAR(160)," "),_xludf.UNICHAR(8239)," ")))="m", LOWER(TRIM(SUBSTITUTE(SUBSTITUTE($I30,CHAR(160)," "),_xludf.UNICHAR(8239)," ")))="males"), "male", IF(OR(LOWER(TRIM(SUBSTITUTE(SUBSTITUTE($I30,CHAR(160)," "),_xludf.UNICHAR(8239)," ")))="female", LOWER(TRIM(SUBSTITUTE(SUBSTITUTE($I30,CHAR(160)," "),_xludf.UNICHAR(8239)," ")))="f", LOWER(TRIM(SUBSTITUTE(SUBSTITUTE($I30,CHAR(160)," "),_xludf.UNICHAR(8239)," ")))="females"), "female", "")) -> #NAME? | K30: 597654109 | L30: Alnussirat | M30: Married | N30: No | P30: Displaced | R30: ANC | X30: =IF(E30="","",UPPER(LEFT($C$3,1)&"-"&LEFT($C$4,1)&"-"&TEXT(ROW(B23),"000")&"-"&TEXT(C30,"dd-mm"))) -> --023-29-03 | Y30: =TRIM(SUBSTITUTE(SUBSTITUTE(OFFSET($Q30,0,COLUMN()-COLUMN($AL$1)),CHAR(160)," "),_xludf.UNICHAR(8239)," ")) -> #NAME? | Z30: =TRIM(SUBSTITUTE(SUBSTITUTE(OFFSET($Q30,0,COLUMN()-COLUMN($AL$1)),CHAR(160)," "),_xludf.UNICHAR(8239)," ")) -> #NAME? | AA30: =TRIM(SUBSTITUTE(SUBSTITUTE(OFFSET($Q30,0,COLUMN()-COLUMN($AL$1)),CHAR(160)," "),_xludf.UNICHAR(8239)," ")) -> #NAME? | AB30: =TRIM(SUBSTITUTE(SUBSTITUTE(OFFSET($Q30,0,COLUMN()-COLUMN($AL$1)),CHAR(160)," "),_xludf.UNICHAR(8239)," ")) -> #NAME? | AC30: =TRIM(SUBSTITUTE(SUBSTITUTE(OFFSET($Q30,0,COLUMN()-COLUMN($AL$1)),CHAR(160)," "),_xludf.UNICHAR(8239)," ")) -> #NAME? | AD30: =IF($E30="",0,--(COUNTIFS($E:$E,$E30,$C:$C,">"&$C30)+COUNTIFS($E$8:E30,$E30,$C$8:C30,$C30)=1)) -> 1 | AE30: =IF($C30="","",TEXT($C30,"yyyy-mm")) -> 2026-03 | AF30: =IF(OR($E30="",$AE30=""),0,IF(COUNTIFS($E$8:E30,$E30,$AE$8:AE30,$AE30)=1,1,0)) -> 1 | AG30: =IF($E30="",0,IF(COUNTIF($E$8:E30,$E30)=1,1,0)) -> 1
A31: 24 | B31: هالة عماد محمود العمرانى | C31: 46110 | D31: {=IFERROR( LOOKUP(2, 1/((TRIM(IMS!$E$8:$E$4000)=TRIM(IMS!$E31))*(IMS!$C$8:$C$4000<IMS!$C31)), IMS!$C$8:$C$4000), "")} | E31: 801519380 | F31: 32036 | G31: 39 | H31: =IF(G31="","",IF(G31<=5,"0-5",IF(G31<=18,"6-18",IF(G31<=60,"19-60","+60")))) -> 19-60 | I31: FEMALE | J31: =IF(OR(LOWER(TRIM(SUBSTITUTE(SUBSTITUTE($I31,CHAR(160)," "),_xludf.UNICHAR(8239)," ")))="male", LOWER(TRIM(SUBSTITUTE(SUBSTITUTE($I31,CHAR(160)," "),_xludf.UNICHAR(8239)," ")))="m", LOWER(TRIM(SUBSTITUTE(SUBSTITUTE($I31,CHAR(160)," "),_xludf.UNICHAR(8239)," ")))="males"), "male", IF(OR(LOWER(TRIM(SUBSTITUTE(SUBSTITUTE($I31,CHAR(160)," "),_xludf.UNICHAR(8239)," ")))="female", LOWER(TRIM(SUBSTITUTE(SUBSTITUTE($I31,CHAR(160)," "),_xludf.UNICHAR(8239)," ")))="f", LOWER(TRIM(SUBSTITUTE(SUBSTITUTE($I31,CHAR(160)," "),_xludf.UNICHAR(8239)," ")))="females"), "female", "")) -> #NAME? | K31: 592894497 | L31: Alnussirat | M31: Married | N31: No | P31: Displaced | Q31: FM- CD | X31: =IF(E31="","",UPPER(LEFT($C$3,1)&"-"&LEFT($C$4,1)&"-"&TEXT(ROW(B24),"000")&"-"&TEXT(C31,"dd-mm"))) -> --024-29-03 | Y31: =TRIM(SUBSTITUTE(SUBSTITUTE(OFFSET($Q31,0,COLUMN()-COLUMN($AL$1)),CHAR(160)," "),_xludf.UNICHAR(8239)," ")) -> #NAME? | Z31: =TRIM(SUBSTITUTE(SUBSTITUTE(OFFSET($Q31,0,COLUMN()-COLUMN($AL$1)),CHAR(160)," "),_xludf.UNICHAR(8239)," ")) -> #NAME? | AA31: =TRIM(SUBSTITUTE(SUBSTITUTE(OFFSET($Q31,0,COLUMN()-COLUMN($AL$1)),CHAR(160)," "),_xludf.UNICHAR(8239)," ")) -> #NAME? | AB31: =TRIM(SUBSTITUTE(SUBSTITUTE(OFFSET($Q31,0,COLUMN()-COLUMN($AL$1)),CHAR(160)," "),_xludf.UNICHAR(8239)," ")) -> #NAME? | AC31: =TRIM(SUBSTITUTE(SUBSTITUTE(OFFSET($Q31,0,COLUMN()-COLUMN($AL$1)),CHAR(160)," "),_xludf.UNICHAR(8239)," ")) -> #NAME? | AD31: =IF($E31="",0,--(COUNTIFS($E:$E,$E31,$C:$C,">"&$C31)+COUNTIFS($E$8:E31,$E31,$C$8:C31,$C31)=1)) -> 0 | AE31: =IF($C31="","",TEXT($C31,"yyyy-mm")) -> 2026-03 | AF31: =IF(OR($E31="",$AE31=""),0,IF(COUNTIFS($E$8:E31,$E31,$AE$8:AE31,$AE31)=1,1,0)) -> 1 | AG31: =IF($E31="",0,IF(COUNTIF($E$8:E31,$E31)=1,1,0)) -> 1
A32: 25 | B32: قمر محمد ابراهيم الكفارة | C32: 46110 | D32: {=IFERROR( LOOKUP(2, 1/((TRIM(IMS!$E$8:$E$4000)=TRIM(IMS!$E32))*(IMS!$C$8:$C$4000<IMS!$C32)), IMS!$C$8:$C$4000), "")} | E32: 400953782 | F32: 35097 | G32: 30 | H32: =IF(G32="","",IF(G32<=5,"0-5",IF(G32<=18,"6-18",IF(G32<=60,"19-60","+60")))) -> 19-60 | I32: FEMALE | J32: =IF(OR(LOWER(TRIM(SUBSTITUTE(SUBSTITUTE($I32,CHAR(160)," "),_xludf.UNICHAR(8239)," ")))="male", LOWER(TRIM(SUBSTITUTE(SUBSTITUTE($I32,CHAR(160)," "),_xludf.UNICHAR(8239)," ")))="m", LOWER(TRIM(SUBSTITUTE(SUBSTITUTE($I32,CHAR(160)," "),_xludf.UNICHAR(8239)," ")))="males"), "male", IF(OR(LOWER(TRIM(SUBSTITUTE(SUBSTITUTE($I32,CHAR(160)," "),_xludf.UNICHAR(8239)," ")))="female", LOWER(TRIM(SUBSTITUTE(SUBSTITUTE($I32,CHAR(160)," "),_xludf.UNICHAR(8239)," ")))="f", LOWER(TRIM(SUBSTITUTE(SUBSTITUTE($I32,CHAR(160)," "),_xludf.UNICHAR(8239)," ")))="females"), "female", "")) -> #NAME? | K32: 592574605 | L32: Alnussirat | M32: Married | N32: No | P32: Displaced | R32: ANC | X32: =IF(E32="","",UPPER(LEFT($C$3,1)&"-"&LEFT($C$4,1)&"-"&TEXT(ROW(B25),"000")&"-"&TEXT(C32,"dd-mm"))) -> --025-29-03 | Y32: =TRIM(SUBSTITUTE(SUBSTITUTE(OFFSET($Q32,0,COLUMN()-COLUMN($AL$1)),CHAR(160)," "),_xludf.UNICHAR(8239)," ")) -> #NAME? | Z32: =TRIM(SUBSTITUTE(SUBSTITUTE(OFFSET($Q32,0,COLUMN()-COLUMN($AL$1)),CHAR(160)," "),_xludf.UNICHAR(8239)," ")) -> #NAME? | AA32: =TRIM(SUBSTITUTE(SUBSTITUTE(OFFSET($Q32,0,COLUMN()-COLUMN($AL$1)),CHAR(160)," "),_xludf.UNICHAR(8239)," ")) -> #NAME? | AB32: =TRIM(SUBSTITUTE(SUBSTITUTE(OFFSET($Q32,0,COLUMN()-COLUMN($AL$1)),CHAR(160)," "),_xludf.UNICHAR(8239)," ")) -> #NAME? | AC32: =TRIM(SUBSTITUTE(SUBSTITUTE(OFFSET($Q32,0,COLUMN()-COLUMN($AL$1)),CHAR(160)," "),_xludf.UNICHAR(8239)," ")) -> #NAME? | AD32: =IF($E32="",0,--(COUNTIFS($E:$E,$E32,$C:$C,">"&$C32)+COUNTIFS($E$8:E32,$E32,$C$8:C32,$C32)=1)) -> 0 | AE32: =IF($C32="","",TEXT($C32,"yyyy-mm")) -> 2026-03 | AF32: =IF(OR($E32="",$AE32=""),0,IF(COUNTIFS($E$8:E32,$E32,$AE$8:AE32,$AE32)=1,1,0)) -> 1 | AG32: =IF($E32="",0,IF(COUNTIF($E$8:E32,$E32)=1,1,0)) -> 1
A33: 26 | B33: شهد اكرم رياض قرضاية | C33: 46110 | D33: {=IFERROR( LOOKUP(2, 1/((TRIM(IMS!$E$8:$E$4000)=TRIM(IMS!$E33))*(IMS!$C$8:$C$4000<IMS!$C33)), IMS!$C$8:$C$4000), "")} | E33: 408480358 | F33: 37822 | G33: 23 | H33: =IF(G33="","",IF(G33<=5,"0-5",IF(G33<=18,"6-18",IF(G33<=60,"19-60","+60")))) -> 19-60 | I33: FEMALE | J33: =IF(OR(LOWER(TRIM(SUBSTITUTE(SUBSTITUTE($I33,CHAR(160)," "),_xludf.UNICHAR(8239)," ")))="male", LOWER(TRIM(SUBSTITUTE(SUBSTITUTE($I33,CHAR(160)," "),_xludf.UNICHAR(8239)," ")))="m", LOWER(TRIM(SUBSTITUTE(SUBSTITUTE($I33,CHAR(160)," "),_xludf.UNICHAR(8239)," ")))="males"), "male", IF(OR(LOWER(TRIM(SUBSTITUTE(SUBSTITUTE($I33,CHAR(160)," "),_xludf.UNICHAR(8239)," ")))="female", LOWER(TRIM(SUBSTITUTE(SUBSTITUTE($I33,CHAR(160)," "),_xludf.UNICHAR(8239)," ")))="f", LOWER(TRIM(SUBSTITUTE(SUBSTITUTE($I33,CHAR(160)," "),_xludf.UNICHAR(8239)," ")))="females"), "female", "")) -> #NAME? | K33: 592581573 | L33: Alnussirat | M33: Single | N33: No | P33: Displaced | Q33: FM- CD | X33: =IF(E33="","",UPPER(LEFT($C$3,1)&"-"&LEFT($C$4,1)&"-"&TEXT(ROW(B26),"000")&"-"&TEXT(C33,"dd-mm"))) -> --026-29-03 | Y33: =TRIM(SUBSTITUTE(SUBSTITUTE(OFFSET($Q33,0,COLUMN()-COLUMN($AL$1)),CHAR(160)," "),_xludf.UNICHAR(8239)," ")) -> #NAME? | Z33: =TRIM(SUBSTITUTE(SUBSTITUTE(OFFSET($Q33,0,COLUMN()-COLUMN($AL$1)),CHAR(160)," "),_xludf.UNICHAR(8239)," ")) -> #NAME? | AA33: =TRIM(SUBSTITUTE(SUBSTITUTE(OFFSET($Q33,0,COLUMN()-COLUMN($AL$1)),CHAR(160)," "),_xludf.UNICHAR(8239)," ")) -> #NAME? | AB33: =TRIM(SUBSTITUTE(SUBSTITUTE(OFFSET($Q33,0,COLUMN()-COLUMN($AL$1)),CHAR(160)," "),_xludf.UNICHAR(8239)," ")) -> #NAME? | AC33: =TRIM(SUBSTITUTE(SUBSTITUTE(OFFSET($Q33,0,COLUMN()-COLUMN($AL$1)),CHAR(160)," "),_xludf.UNICHAR(8239)," ")) -> #NAME? | AD33: =IF($E33="",0,--(COUNTIFS($E:$E,$E33,$C:$C,">"&$C33)+COUNTIFS($E$8:E33,$E33,$C$8:C33,$C33)=1)) -> 1 | AE33: =IF($C33="","",TEXT($C33,"yyyy-mm")) -> 2026-03 | AF33: =IF(OR($E33="",$AE33=""),0,IF(COUNTIFS($E$8:E33,$E33,$AE$8:AE33,$AE33)=1,1,0)) -> 1 | AG33: =IF($E33="",0,IF(COUNTIF($E$8:E33,$E33)=1,1,0)) -> 1
A34: 27 | B34: حسن جبريل احمد قرضاية | C34: 46110 | D34: {=IFERROR( LOOKUP(2, 1/((TRIM(IMS!$E$8:$E$4000)=TRIM(IMS!$E34))*(IMS!$C$8:$C$4000<IMS!$C34)), IMS!$C$8:$C$4000), "")} | E34: 926952045 | F34: 19004 | G34: 74 | H34: =IF(G34="","",IF(G34<=5,"0-5",IF(G34<=18,"6-18",IF(G34<=60,"19-60","+60")))) -> +60 | I34: FEMALE | J34: =IF(OR(LOWER(TRIM(SUBSTITUTE(SUBSTITUTE($I34,CHAR(160)," "),_xludf.UNICHAR(8239)," ")))="male", LOWER(TRIM(SUBSTITUTE(SUBSTITUTE($I34,CHAR(160)," "),_xludf.UNICHAR(8239)," ")))="m", LOWER(TRIM(SUBSTITUTE(SUBSTITUTE($I34,CHAR(160)," "),_xludf.UNICHAR(8239)," ")))="males"), "male", IF(OR(LOWER(TRIM(SUBSTITUTE(SUBSTITUTE($I34,CHAR(160)," "),_xludf.UNICHAR(8239)," ")))="female", LOWER(TRIM(SUBSTITUTE(SUBSTITUTE($I34,CHAR(160)," "),_xludf.UNICHAR(8239)," ")))="f", LOWER(TRIM(SUBSTITUTE(SUBSTITUTE($I34,CHAR(160)," "),_xludf.UNICHAR(8239)," ")))="females"), "female", "")) -> #NAME? | K34: 599260878 | L34: Alnussirat | M34: Widowed | N34: No | P34: Displaced | Q34: FM- NCD | X34: =IF(E34="","",UPPER(LEFT($C$3,1)&"-"&LEFT($C$4,1)&"-"&TEXT(ROW(B27),"000")&"-"&TEXT(C34,"dd-mm"))) -> --027-29-03 | Y34: =TRIM(SUBSTITUTE(SUBSTITUTE(OFFSET($Q36,0,COLUMN()-COLUMN($AL$1)),CHAR(160)," "),_xludf.UNICHAR(8239)," ")) -> #NAME? | Z34: =TRIM(SUBSTITUTE(SUBSTITUTE(OFFSET($Q36,0,COLUMN()-COLUMN($AL$1)),CHAR(160)," "),_xludf.UNICHAR(8239)," ")) -> #NAME? | AA34: =TRIM(SUBSTITUTE(SUBSTITUTE(OFFSET($Q36,0,COLUMN()-COLUMN($AL$1)),CHAR(160)," "),_xludf.UNICHAR(8239)," ")) -> #NAME? | AB34: =TRIM(SUBSTITUTE(SUBSTITUTE(OFFSET($Q36,0,COLUMN()-COLUMN($AL$1)),CHAR(160)," "),_xludf.UNICHAR(8239)," ")) -> #NAME? | AC34: =TRIM(SUBSTITUTE(SUBSTITUTE(OFFSET($Q36,0,COLUMN()-COLUMN($AL$1)),CHAR(160)," "),_xludf.UNICHAR(8239)," ")) -> #NAME? | AD34: =IF($E34="",0,--(COUNTIFS($E:$E,$E34,$C:$C,">"&$C34)+COUNTIFS($E$8:E34,$E34,$C$8:C34,$C34)=1)) -> 1 | AE34: =IF($C34="","",TEXT($C34,"yyyy-mm")) -> 2026-03 | AF34: =IF(OR($E34="",$AE34=""),0,IF(COUNTIFS($E$8:E34,$E34,$AE$8:AE34,$AE34)=1,1,0)) -> 1 | AG34: =IF($E34="",0,IF(COUNTIF($E$8:E34,$E34)=1,1,0)) -> 1
A35: 28 | B35: كندا محمد فؤاد الحلبى | C35: 46110 | D35: {=IFERROR( LOOKUP(2, 1/((TRIM(IMS!$E$8:$E$4000)=TRIM(IMS!$E35))*(IMS!$C$8:$C$4000<IMS!$C35)), IMS!$C$8:$C$4000), "")} | E35: 443104294 | F35: 43974 | G35: 6 | H35: =IF(G35="","",IF(G35<=5,"0-5",IF(G35<=18,"6-18",IF(G35<=60,"19-60","+60")))) -> 6-18 | I35: FEMALE | J35: =IF(OR(LOWER(TRIM(SUBSTITUTE(SUBSTITUTE($I35,CHAR(160)," "),_xludf.UNICHAR(8239)," ")))="male", LOWER(TRIM(SUBSTITUTE(SUBSTITUTE($I35,CHAR(160)," "),_xludf.UNICHAR(8239)," ")))="m", LOWER(TRIM(SUBSTITUTE(SUBSTITUTE($I35,CHAR(160)," "),_xludf.UNICHAR(8239)," ")))="males"), "male", IF(OR(LOWER(TRIM(SUBSTITUTE(SUBSTITUTE($I35,CHAR(160)," "),_xludf.UNICHAR(8239)," ")))="female", LOWER(TRIM(SUBSTITUTE(SUBSTITUTE($I35,CHAR(160)," "),_xludf.UNICHAR(8239)," ")))="f", LOWER(TRIM(SUBSTITUTE(SUBSTITUTE($I35,CHAR(160)," "),_xludf.UNICHAR(8239)," ")))="females"), "female", "")) -> #NAME? | K35: 597152085 | L35: Alnussirat | M35: N/A | N35: No | P35: Displaced | Q35: FM- CD | X35: =IF(E35="","",UPPER(LEFT($C$3,1)&"-"&LEFT($C$4,1)&"-"&TEXT(ROW(B28),"000")&"-"&TEXT(C35,"dd-mm"))) -> --028-29-03 | Y35: =TRIM(SUBSTITUTE(SUBSTITUTE(OFFSET($Q35,0,COLUMN()-COLUMN($AL$1)),CHAR(160)," "),_xludf.UNICHAR(8239)," ")) -> #NAME? | Z35: =TRIM(SUBSTITUTE(SUBSTITUTE(OFFSET($Q35,0,COLUMN()-COLUMN($AL$1)),CHAR(160)," "),_xludf.UNICHAR(8239)," ")) -> #NAME? | AA35: =TRIM(SUBSTITUTE(SUBSTITUTE(OFFSET($Q35,0,COLUMN()-COLUMN($AL$1)),CHAR(160)," "),_xludf.UNICHAR(8239)," ")) -> #NAME? | AB35: =TRIM(SUBSTITUTE(SUBSTITUTE(OFFSET($Q35,0,COLUMN()-COLUMN($AL$1)),CHAR(160)," "),_xludf.UNICHAR(8239)," ")) -> #NAME? | AC35: =TRIM(SUBSTITUTE(SUBSTITUTE(OFFSET($Q35,0,COLUMN()-COLUMN($AL$1)),CHAR(160)," "),_xludf.UNICHAR(8239)," ")) -> #NAME? | AD35: =IF($E35="",0,--(COUNTIFS($E:$E,$E35,$C:$C,">"&$C35)+COUNTIFS($E$8:E35,$E35,$C$8:C35,$C35)=1)) -> 0 | AE35: =IF($C35="","",TEXT($C35,"yyyy-mm")) -> 2026-03 | AF35: =IF(OR($E35="",$AE35=""),0,IF(COUNTIFS($E$8:E35,$E35,$AE$8:AE35,$AE35)=1,1,0)) -> 1 | AG35: =IF($E35="",0,IF(COUNTIF($E$8:E35,$E35)=1,1,0)) -> 1
