Workbook

Sheet IMS
A1: (Partner Name) in partnership with Medical Aid for Palestinains- MAP UK | L1: المصدر | M1: شمال Gaza City | P1: غير معدي | Q1: FM- NCD | R1: ANC | S1: Dressing | T1: Screening | U1: Screening | AM1: فحص | AU1: فحص سوء التغذية
A2: Project: | C2: Improving Access to Comprehensive Primary Health Care and Protection in Gaza | L2: Alzawida | M2: Gaza City | O2: قبل الحمل | P2: PCC | Q2: FM- CD | R2: PNC | S2: Follow-up Dressing | T2: Screening and Referral | U2: SAM referral | AM2: تحويل SAM | AU2: سوء تغذية شديد
A3: Partner: | L3: Dier Albalah | M3: الزهراء | Q3: ENT | R3: FP | S3: Wound Cleaning | U3: MAM referral | AM3: تحويل MAM | AU3: سوء تغذية متوسط
A4: Medical Point: | L4: خانيونس | M4: Alnussirat | Q4: Derma | R4: GYN | S4: Suture Removal | AM4: —
A5: Month | L5: مواصي خانيونس | M5: Alburaij
A6: Governorate | L6: رفح | M6: Almaghazi | P6: Displaced | Q6: Service Matrix | W6: موعد الحجز
A7: # | B7: Full Name/الإسم الكامل | C7: Visit Date/تاريخ الزيارة | D7: Last Visit Date/تاريخ آخر زيارة | E7: ID N./رقم الهوية | F7: Date of Birth/ تاريخ الميلاد | G7: Age/العمر | H7: Age Group/الفئة العمرية | I7: Gender/الجنس | J7: Gender_N | K7: Phone N./الهاتف | L7: Governorate/المحافظة | M7: Social Status/الحالة الاجتماعية | N7: Disability Status/الإعاقة | O7: Disability Type/نوع الإعاقة | P7: Displacment Tracker | Q7: FM services | R7: SRH services | S7: Wound Care | T7: Breast Cancer | U7: Mal-Nutirition | V7: Referral/التحويلات | W7: Follow-up Date/موعد المتابعة | X7: Visitor Code/رمز الزائر | Y7: FM-N | Z7: SRH-N | AA7: Other1_N | AB7: Other2_N | AC7: Other3_N | AD7: Unique Flag | AE7: Visit Month | AF7: Unique in Month Flag | AG7: First Time in Project Flag
A8: 1 | B8: غصون فوزي محمد ابو زيد | C8: 2026-04-26 | E8: 700358666 | F8: 1988-09-01 | G8: 37 | H8: 19-60 | I8: Female | J8: female | K8: 592144734 | L8: Almaghazi | M8: Married | N8: No | P8: Displaced | R8: GYN | X8: =IF(E8="","",UPPER(LEFT($C$3,1)&"-"&LEFT($C$4,1)&"-"&TEXT(ROW(B1),"000")&"-"&TEXT(C8,"dd-mm"))) -> --001-26-04 | Y8: =TRIM(SUBSTITUTE(SUBSTITUTE(OFFSET($Q8,0,COLUMN()-COLUMN($AL$1)),CHAR(160)," "),_xludf.UNICHAR(8239)," ")) -> #NAME? | Z8: =TRIM(SUBSTITUTE(SUBSTITUTE(OFFSET($Q8,0,COLUMN()-COLUMN($AL$1)),CHAR(160)," "),_xludf.UNICHAR(8239)," ")) -> #NAME? | AA8: =TRIM(SUBSTITUTE(SUBSTITUTE(OFFSET($Q8,0,COLUMN()-COLUMN($AL$1)),CHAR(160)," "),_xludf.UNICHAR(8239)," ")) -> #NAME? | AB8: =TRIM(SUBSTITUTE(SUBSTITUTE(OFFSET($Q8,0,COLUMN()-COLUMN($AL$1)),CHAR(160)," "),_xludf.UNICHAR(8239)," ")) -> #NAME? | AC8: =TRIM(SUBSTITUTE(SUBSTITUTE(OFFSET($Q8,0,COLUMN()-COLUMN($AL$1)),CHAR(160)," "),_xludf.UNICHAR(8239)," ")) -> #NAME? | AD8: =IF($E8="",0,--(COUNTIFS($E:$E,$E8,$C:$C,">"&$C8)+COUNTIFS($E$8:E8,$E8,$C$8:C8,$C8)=1)) -> 1 | AE8: =IF($C8="","",TEXT($C8,"yyyy-mm")) -> 2026-04 | AF8: =IF(OR($E8="",$AE8=""),0,IF(COUNTIFS($E$8:E8,$E8,$AE$8:AE8,$AE8)=1,1,0)) -> 1 | AG8: =IF($E8="",0,IF(COUNTIF($E$8:E8,$E8)=1,1,0)) -> 1
A9: 2 | B9: عايشة محمد صالح الدسوقي | C9: 2026-04-26 | E9: 910717982 | F9: 1968-05-07 | G9: 57 | H9: 19-60 | I9: Female | J9: female | K9: 599454954 | L9: Alnussirat | M9: Married | N9: No | P9: Displaced | R9: GYN | X9: =IF(E9="","",UPPER(LEFT($C$3,1)&"-"&LEFT($C$4,1)&"-"&TEXT(ROW(B2),"000")&"-"&TEXT(C9,"dd-mm"))) -> --002-26-04 | Y9: =TRIM(SUBSTITUTE(SUBSTITUTE(OFFSET($Q9,0,COLUMN()-COLUMN($AL$1)),CHAR(160)," "),_xludf.UNICHAR(8239)," ")) -> #NAME? | Z9: =TRIM(SUBSTITUTE(SUBSTITUTE(OFFSET($Q9,0,COLUMN()-COLUMN($AL$1)),CHAR(160)," "),_xludf.UNICHAR(8239)," ")) -> #NAME? | AA9: =TRIM(SUBSTITUTE(SUBSTITUTE(OFFSET($Q9,0,COLUMN()-COLUMN($AL$1)),CHAR(160)," "),_xludf.UNICHAR(8239)," ")) -> #NAME? | AB9: =TRIM(SUBSTITUTE(SUBSTITUTE(OFFSET($Q9,0,COLUMN()-COLUMN($AL$1)),CHAR(160)," "),_xludf.UNICHAR(8239)," ")) -> #NAME? | AC9: =TRIM(SUBSTITUTE(SUBSTITUTE(OFFSET($Q9,0,COLUMN()-COLUMN($AL$1)),CHAR(160)," "),_xludf.UNICHAR(8239)," ")) -> #NAME? | AD9: =IF($E9="",0,--(COUNTIFS($E:$E,$E9,$C:$C,">"&$C9)+COUNTIFS($E$8:E9,$E9,$C$8:C9,$C9)=1)) -> 1 | AE9: =IF($C9="","",TEXT($C9,"yyyy-mm")) -> 2026-04 | AF9: =IF(OR($E9="",$AE9=""),0,IF(COUNTIFS($E$8:E9,$E9,$AE$8:AE9,$AE9)=1,1,0)) -> 1 | AG9: =IF($E9="",0,IF(COUNTIF($E$8:E9,$E9)=1,1,0)) -> 1
A10: 3 | B10: هبة إبراهيم محمد الهبيل | C10: 2026-04-26 | E10: 402516355 | F10: 1997-10-09 | G10: 28 | H10: 19-60 | I10: Female | J10: female | K10: 597054651 | L10: Alnussirat | M10: Married | N10: No | P10: Displaced | R10: FP | X10: =IF(E10="","",UPPER(LEFT($C$3,1)&"-"&LEFT($C$4,1)&"-"&TEXT(ROW(B3),"000")&"-"&TEXT(C10,"dd-mm"))) -> --003-26-04 | Y10: =TRIM(SUBSTITUTE(SUBSTITUTE(OFFSET($Q10,0,COLUMN()-COLUMN($AL$1)),CHAR(160)," "),_xludf.UNICHAR(8239)," ")) -> #NAME? | Z10: =TRIM(SUBSTITUTE(SUBSTITUTE(OFFSET($Q10,0,COLUMN()-COLUMN($AL$1)),CHAR(160)," "),_xludf.UNICHAR(8239)," ")) -> #NAME? | AA10: =TRIM(SUBSTITUTE(SUBSTITUTE(OFFSET($Q10,0,COLUMN()-COLUMN($AL$1)),CHAR(160)," "),_xludf.UNICHAR(8239)," ")) -> #NAME? | AB10: =TRIM(SUBSTITUTE(SUBSTITUTE(OFFSET($Q10,0,COLUMN()-COLUMN($AL$1)),CHAR(160)," "),_xludf.UNICHAR(8239)," ")) -> #NAME? | AC10: =TRIM(SUBSTITUTE(SUBSTITUTE(OFFSET($Q10,0,COLUMN()-COLUMN($AL$1)),CHAR(160)," "),_xludf.UNICHAR(8239)," ")) -> #NAME? | AD10: =IF($E10="",0,--(COUNTIFS($E:$E,$E10,$C:$C,">"&$C10)+COUNTIFS($E$8:E10,$E10,$C$8:C10,$C10)=1)) -> 1 | AE10: =IF($C10="","",TEXT($C10,"yyyy-mm")) -> 2026-04 | AF10: =IF(OR($E10="",$AE10=""),0,IF(COUNTIFS($E$8:E10,$E10,$AE$8:AE10,$AE10)=1,1,0)) -> 1 | AG10: =IF($E10="",0,IF(COUNTIF($E$8:E10,$E10)=1,1,0)) -> 1
A11: 4 | B11: بيسان يحيى ابراهيم وشاح | C11: 2026-04-26 | E11: 412620361 | F11: 1990-04-01 | G11: 36 | H11: 19-60 | I11: Female | J11: female | K11: 592661238 | L11: Alnussirat | M11: Married | N11: No | P11: Displaced | R11: ANC | U11: Screening | X11: =IF(E11="","",UPPER(LEFT($C$3,1)&"-"&LEFT($C$4,1)&"-"&TEXT(ROW(B4),"000")&"-"&TEXT(C11,"dd-mm"))) -> --004-26-04 | Y11: =TRIM(SUBSTITUTE(SUBSTITUTE(OFFSET($Q11,0,COLUMN()-COLUMN($AL$1)),CHAR(160)," "),_xludf.UNICHAR(8239)," ")) -> #NAME? | Z11: =TRIM(SUBSTITUTE(SUBSTITUTE(OFFSET($Q11,0,COLUMN()-COLUMN($AL$1)),CHAR(160)," "),_xludf.UNICHAR(8239)," ")) -> #NAME? | AA11: =TRIM(SUBSTITUTE(SUBSTITUTE(OFFSET($Q11,0,COLUMN()-COLUMN($AL$1)),CHAR(160)," "),_xludf.UNICHAR(8239)," ")) -> #NAME? | AB11: =TRIM(SUBSTITUTE(SUBSTITUTE(OFFSET($Q11,0,COLUMN()-COLUMN($AL$1)),CHAR(160)," "),_xludf.UNICHAR(8239)," ")) -> #NAME? | AC11: =TRIM(SUBSTITUTE(SUBSTITUTE(OFFSET($Q11,0,COLUMN()-COLUMN($AL$1)),CHAR(160)," "),_xludf.UNICHAR(8239)," ")) -> #NAME? | AD11: =IF($E11="",0,--(COUNTIFS($E:$E,$E11,$C:$C,">"&$C11)+COUNTIFS($E$8:E11,$E11,$C$8:C11,$C11)=1)) -> 1 | AE11: =IF($C11="","",TEXT($C11,"yyyy-mm")) -> 2026-04 | AF11: =IF(OR($E11="",$AE11=""),0,IF(COUNTIFS($E$8:E11,$E11,$AE$8:AE11,$AE11)=1,1,0)) -> 1 | AG11: =IF($E11="",0,IF(COUNTIF($E$8:E11,$E11)=1,1,0)) -> 1
A12: 5 | B12: فاطمة صبحي محمد القيق | C12: 2026-04-26 | E12: 800779381 | F12: 1990-06-14 | G12: 35 | H12: 19-60 | I12: Female | J12: female | K12: 595627804 | L12: Alnussirat | M12: Married | N12: No | P12: Displaced | R12: ANC | U12: Screening | X12: =IF(E12="","",UPPER(LEFT($C$3,1)&"-"&LEFT($C$4,1)&"-"&TEXT(ROW(B5),"000")&"-"&TEXT(C12,"dd-mm"))) -> --005-26-04 | Y12: =TRIM(SUBSTITUTE(SUBSTITUTE(OFFSET($Q12,0,COLUMN()-COLUMN($AL$1)),CHAR(160)," "),_xludf.UNICHAR(8239)," ")) -> #NAME? | Z12: =TRIM(SUBSTITUTE(SUBSTITUTE(OFFSET($Q12,0,COLUMN()-COLUMN($AL$1)),CHAR(160)," "),_xludf.UNICHAR(8239)," ")) -> #NAME? | AA12: =TRIM(SUBSTITUTE(SUBSTITUTE(OFFSET($Q12,0,COLUMN()-COLUMN($AL$1)),CHAR(160)," "),_xludf.UNICHAR(8239)," ")) -> #NAME? | AB12: =TRIM(SUBSTITUTE(SUBSTITUTE(OFFSET($Q12,0,COLUMN()-COLUMN($AL$1)),CHAR(160)," "),_xludf.UNICHAR(8239)," ")) -> #NAME? | AC12: =TRIM(SUBSTITUTE(SUBSTITUTE(OFFSET($Q12,0,COLUMN()-COLUMN($AL$1)),CHAR(160)," "),_xludf.UNICHAR(8239)," ")) -> #NAME? | AD12: =IF($E12="",0,--(COUNTIFS($E:$E,$E12,$C:$C,">"&$C12)+COUNTIFS($E$8:E12,$E12,$C$8:C12,$C12)=1)) -> 1 | AE12: =IF($C12="","",TEXT($C12,"yyyy-mm")) -> 2026-04 | AF12: =IF(OR($E12="",$AE12=""),0,IF(COUNTIFS($E$8:E12,$E12,$AE$8:AE12,$AE12)=1,1,0)) -> 1 | AG12: =IF($E12="",0,IF(COUNTIF($E$8:E12,$E12)=1,1,0)) -> 1
A13: 6 | B13: يوسف رامي خليل القيق | C13: 2026-04-26 | E13: 438175176 | F13: 2016-09-22 | G13: 9 | H13: 6-18 | I13: Male | J13: male | K13: 599933654 | L13: Alnussirat | M13: N/A | N13: No | P13: Displaced | Q13: FM- CD | X13: =IF(E13="","",UPPER(LEFT($C$3,1)&"-"&LEFT($C$4,1)&"-"&TEXT(ROW(B6),"000")&"-"&TEXT(C13,"dd-mm"))) -> --006-26-04 | Y13: =TRIM(SUBSTITUTE(SUBSTITUTE(OFFSET($Q13,0,COLUMN()-COLUMN($AL$1)),CHAR(160)," "),_xludf.UNICHAR(8239)," ")) -> #NAME? | Z13: =TRIM(SUBSTITUTE(SUBSTITUTE(OFFSET($Q13,0,COLUMN()-COLUMN($AL$1)),CHAR(160)," "),_xludf.UNICHAR(8239)," ")) -> #NAME? | AA13: =TRIM(SUBSTITUTE(SUBSTITUTE(OFFSET($Q13,0,COLUMN()-COLUMN($AL$1)),CHAR(160)," "),_xludf.UNICHAR(8239)," ")) -> #NAME? | AB13: =TRIM(SUBSTITUTE(SUBSTITUTE(OFFSET($Q13,0,COLUMN()-COLUMN($AL$1)),CHAR(160)," "),_xludf.UNICHAR(8239)," ")) -> #NAME? | AC13: =TRIM(SUBSTITUTE(SUBSTITUTE(OFFSET($Q13,0,COLUMN()-COLUMN($AL$1)),CHAR(160)," "),_xludf.UNICHAR(8239)," ")) -> #NAME? | AD13: =IF($E13="",0,--(COUNTIFS($E:$E,$E13,$C:$C,">"&$C13)+COUNTIFS($E$8:E13,$E13,$C$8:C13,$C13)=1)) -> 1 | AE13: =IF($C13="","",TEXT($C13,"yyyy-mm")) -> 2026-04 | AF13: =IF(OR($E13="",$AE13=""),0,IF(COUNTIFS($E$8:E13,$E13,$AE$8:AE13,$AE13)=1,1,0)) -> 1 | AG13: =IF($E13="",0,IF(COUNTIF($E$8:E13,$E13)=1,1,0)) -> 1
A14: 7 | B14: محمد عيسى عبد الناضر عيسى | C14: 2026-04-26 | E14: 470066614 | F14: 2024-03-27 | G14: 2 | H14: 0-5 | I14: Female | J14: female | K14: 596546496 | L14: Alnussirat | M14: N/A | N14: No | P14: Displaced | Q14: FM- CD | X14: =IF(E14="","",UPPER(LEFT($C$3,1)&"-"&LEFT($C$4,1)&"-"&TEXT(ROW(B7),"000")&"-"&TEXT(C14,"dd-mm"))) -> --007-26-04 | Y14: =TRIM(SUBSTITUTE(SUBSTITUTE(OFFSET($Q14,0,COLUMN()-COLUMN($AL$1)),CHAR(160)," "),_xludf.UNICHAR(8239)," ")) -> #NAME? | Z14: =TRIM(SUBSTITUTE(SUBSTITUTE(OFFSET($Q14,0,COLUMN()-COLUMN($AL$1)),CHAR(160)," "),_xludf.UNICHAR(8239)," ")) -> #NAME? | AA14: =TRIM(SUBSTITUTE(SUBSTITUTE(OFFSET($Q14,0,COLUMN()-COLUMN($AL$1)),CHAR(160)," "),_xludf.UNICHAR(8239)," ")) -> #NAME? | AB14: =TRIM(SUBSTITUTE(SUBSTITUTE(OFFSET($Q14,0,COLUMN()-COLUMN($AL$1)),CHAR(160)," "),_xludf.UNICHAR(8239)," ")) -> #NAME? | AC14: =TRIM(SUBSTITUTE(SUBSTITUTE(OFFSET($Q14,0,COLUMN()-COLUMN($AL$1)),CHAR(160)," "),_xludf.UNICHAR(8239)," ")) -> #NAME? | AD14: =IF($E14="",0,--(COUNTIFS($E:$E,$E14,$C:$C,">"&$C14)+COUNTIFS($E$8:E14,$E14,$C$8:C14,$C14)=1)) -> 1 | AE14: =IF($C14="","",TEXT($C14,"yyyy-mm")) -> 2026-04 | AF14: =IF(OR($E14="",$AE14=""),0,IF(COUNTIFS($E$8:E14,$E14,$AE$8:AE14,$AE14)=1,1,0)) -> 1 | AG14: =IF($E14="",0,IF(COUNTIF($E$8:E14,$E14)=1,1,0)) -> 1
A15: 8 | B15: روزين حسن صقر ابو سليسل | C15: 2026-04-26 | E15: 903078541 | F15: 1980-03-03 | G15: 46 | H15: 19-60 | I15: Female | J15: female | K15: 599056341 | L15: Alnussirat | M15: Married | N15: No | P15: Displaced | R15: ANC | U15: Screening | X15: =IF(E15="","",UPPER(LEFT($C$3,1)&"-"&LEFT($C$4,1)&"-"&TEXT(ROW(B8),"000")&"-"&TEXT(C15,"dd-mm"))) -> --008-26-04 | Y15: =TRIM(SUBSTITUTE(SUBSTITUTE(OFFSET($Q15,0,COLUMN()-COLUMN($AL$1)),CHAR(160)," "),_xludf.UNICHAR(8239)," ")) -> #NAME? | Z15: =TRIM(SUBSTITUTE(SUBSTITUTE(OFFSET($Q15,0,COLUMN()-COLUMN($AL$1)),CHAR(160)," "),_xludf.UNICHAR(8239)," ")) -> #NAME? | AA15: =TRIM(SUBSTITUTE(SUBSTITUTE(OFFSET($Q15,0,COLUMN()-COLUMN($AL$1)),CHAR(160)," "),_xludf.UNICHAR(8239)," ")) -> #NAME? | AB15: =TRIM(SUBSTITUTE(SUBSTITUTE(OFFSET($Q15,0,COLUMN()-COLUMN($AL$1)),CHAR(160)," "),_xludf.UNICHAR(8239)," ")) -> #NAME? | AC15: =TRIM(SUBSTITUTE(SUBSTITUTE(OFFSET($Q15,0,COLUMN()-COLUMN($AL$1)),CHAR(160)," "),_xludf.UNICHAR(8239)," ")) -> #NAME? | AD15: =IF($E15="",0,--(COUNTIFS($E:$E,$E15,$C:$C,">"&$C15)+COUNTIFS($E$8:E15,$E15,$C$8:C15,$C15)=1)) -> 1 | AE15: =IF($C15="","",TEXT($C15,"yyyy-mm")) -> 2026-04 | AF15: =IF(OR($E15="",$AE15=""),0,IF(COUNTIFS($E$8:E15,$E15,$AE$8:AE15,$AE15)=1,1,0)) -> 1 | AG15: =IF($E15="",0,IF(COUNTIF($E$8:E15,$E15)=1,1,0)) -> 1
A16: 9 | B16: رواء ماهر سلامة منصور | C16: 2026-04-26 | E16: 801828559 | F16: 1988-02-18 | G16: 38 | H16: 19-60 | I16: Female | J16: female | K16: 598282280 | L16: Alnussirat | M16: Married | N16: No | P16: Displaced | R16: FP | X16: =IF(E16="","",UPPER(LEFT($C$3,1)&"-"&LEFT($C$4,1)&"-"&TEXT(ROW(B9),"000")&"-"&TEXT(C16,"dd-mm"))) -> --009-26-04 | Y16: =TRIM(SUBSTITUTE(SUBSTITUTE(OFFSET($Q16,0,COLUMN()-COLUMN($AL$1)),CHAR(160)," "),_xludf.UNICHAR(8239)," ")) -> #NAME? | Z16: =TRIM(SUBSTITUTE(SUBSTITUTE(OFFSET($Q16,0,COLUMN()-COLUMN($AL$1)),CHAR(160)," "),_xludf.UNICHAR(8239)," ")) -> #NAME? | AA16: =TRIM(SUBSTITUTE(SUBSTITUTE(OFFSET($Q16,0,COLUMN()-COLUMN($AL$1)),CHAR(160)," "),_xludf.UNICHAR(8239)," ")) -> #NAME? | AB16: =TRIM(SUBSTITUTE(SUBSTITUTE(OFFSET($Q16,0,COLUMN()-COLUMN($AL$1)),CHAR(160)," "),_xludf.UNICHAR(8239)," ")) -> #NAME? | AC16: =TRIM(SUBSTITUTE(SUBSTITUTE(OFFSET($Q16,0,COLUMN()-COLUMN($AL$1)),CHAR(160)," "),_xludf.UNICHAR(8239)," ")) -> #NAME? | AD16: =IF($E16="",0,--(COUNTIFS($E:$E,$E16,$C:$C,">"&$C16)+COUNTIFS($E$8:E16,$E16,$C$8:C16,$C16)=1)) -> 1 | AE16: =IF($C16="","",TEXT($C16,"yyyy-mm")) -> 2026-04 | AF16: =IF(OR($E16="",$AE16=""),0,IF(COUNTIFS($E$8:E16,$E16,$AE$8:AE16,$AE16)=1,1,0)) -> 1 | AG16: =IF($E16="",0,IF(COUNTIF($E$8:E16,$E16)=1,1,0)) -> 1
A17: 10 | B17: غزل حسام محمد ابو جحجوح | C17: 2026-04-26 | E17: 426241790 | F17: 2008-12-27 | G17: 17 | H17: 6-18 | I17: Female | J17: female | K17: 599867041 | L17: Alnussirat | M17: Single | N17: No | P17: Displaced | R17: GYN | X17: =IF(E17="","",UPPER(LEFT($C$3,1)&"-"&LEFT($C$4,1)&"-"&TEXT(ROW(B10),"000")&"-"&TEXT(C17,"dd-mm"))) -> --010-26-04 | Y17: =TRIM(SUBSTITUTE(SUBSTITUTE(OFFSET($Q17,0,COLUMN()-COLUMN($AL$1)),CHAR(160)," "),_xludf.UNICHAR(8239)," ")) -> #NAME? | Z17: =TRIM(SUBSTITUTE(SUBSTITUTE(OFFSET($Q17,0,COLUMN()-COLUMN($AL$1)),CHAR(160)," "),_xludf.UNICHAR(8239)," ")) -> #NAME? | AA17: =TRIM(SUBSTITUTE(SUBSTITUTE(OFFSET($Q17,0,COLUMN()-COLUMN($AL$1)),CHAR(160)," "),_xludf.UNICHAR(8239)," ")) -> #NAME? | AB17: =TRIM(SUBSTITUTE(SUBSTITUTE(OFFSET($Q17,0,COLUMN()-COLUMN($AL$1)),CHAR(160)," "),_xludf.UNICHAR(8239)," ")) -> #NAME? | AC17: =TRIM(SUBSTITUTE(SUBSTITUTE(OFFSET($Q17,0,COLUMN()-COLUMN($AL$1)),CHAR(160)," "),_xludf.UNICHAR(8239)," ")) -> #NAME? | AD17: =IF($E17="",0,--(COUNTIFS($E:$E,$E17,$C:$C,">"&$C17)+COUNTIFS($E$8:E17,$E17,$C$8:C17,$C17)=1)) -> 1 | AE17: =IF($C17="","",TEXT($C17,"yyyy-mm")) -> 2026-04 | AF17: =IF(OR($E17="",$AE17=""),0,IF(COUNTIFS($E$8:E17,$E17,$AE$8:AE17,$AE17)=1,1,0)) -> 1 | AG17: =IF($E17="",0,IF(COUNTIF($E$8:E17,$E17)=1,1,0)) -> 1
A18: 11 | B18: عبدالله محمد جميل ابو خاطر | C18: 2026-04-26 | E18: 444703276 | F18: 2024-12-10 | G18: 1 | H18: 0-5 | I18: Male | J18: male | K18: 595196074 | L18: Alnussirat | M18: N/A | N18: No | P18: Displaced | Q18: FM- CD | X18: =IF(E18="","",UPPER(LEFT($C$3,1)&"-"&LEFT($C$4,1)&"-"&TEXT(ROW(B11),"000")&"-"&TEXT(C18,"dd-mm"))) -> --011-26-04 | Y18: =TRIM(SUBSTITUTE(SUBSTITUTE(OFFSET($Q18,0,COLUMN()-COLUMN($AL$1)),CHAR(160)," "),_xludf.UNICHAR(8239)," ")) -> #NAME? | Z18: =TRIM(SUBSTITUTE(SUBSTITUTE(OFFSET($Q18,0,COLUMN()-COLUMN($AL$1)),CHAR(160)," "),_xludf.UNICHAR(8239)," ")) -> #NAME? | AA18: =TRIM(SUBSTITUTE(SUBSTITUTE(OFFSET($Q18,0,COLUMN()-COLUMN($AL$1)),CHAR(160)," "),_xludf.UNICHAR(8239)," ")) -> #NAME? | AB18: =TRIM(SUBSTITUTE(SUBSTITUTE(OFFSET($Q18,0,COLUMN()-COLUMN($AL$1)),CHAR(160)," "),_xludf.UNICHAR(8239)," ")) -> #NAME? | AC18: =TRIM(SUBSTITUTE(SUBSTITUTE(OFFSET($Q18,0,COLUMN()-COLUMN($AL$1)),CHAR(160)," "),_xludf.UNICHAR(8239)," ")) -> #NAME? | AD18: =IF($E18="",0,--(COUNTIFS($E:$E,$E18,$C:$C,">"&$C18)+COUNTIFS($E$8:E18,$E18,$C$8:C18,$C18)=1)) -> 1 | AE18: =IF($C18="","",TEXT($C18,"yyyy-mm")) -> 2026-04 | AF18: =IF(OR($E18="",$AE18=""),0,IF(COUNTIFS($E$8:E18,$E18,$AE$8:AE18,$AE18)=1,1,0)) -> 1 | AG18: =IF($E18="",0,IF(COUNTIF($E$8:E18,$E18)=1,1,0)) -> 1
A19: 12 | B19: سجى محمد كامل ابو خاطر | C19: 2026-04-26 | E19: 408794253 | F19: 2003-06-04 | G19: 22 | H19: 19-60 | I19: Female | J19: female | K19: 595304423 | L19: Alnussirat | M19: Married | N19: No | P19: Displaced | R19: GYN | X19: =IF(E19="","",UPPER(LEFT($C$3,1)&"-"&LEFT($C$4,1)&"-"&TEXT(ROW(B12),"000")&"-"&TEXT(C19,"dd-mm"))) -> --012-26-04 | Y19: =TRIM(SUBSTITUTE(SUBSTITUTE(OFFSET($Q19,0,COLUMN()-COLUMN($AL$1)),CHAR(160)," "),_xludf.UNICHAR(8239)," ")) -> #NAME? | Z19: =TRIM(SUBSTITUTE(SUBSTITUTE(OFFSET($Q19,0,COLUMN()-COLUMN($AL$1)),CHAR(160)," "),_xludf.UNICHAR(8239)," ")) -> #NAME? | AA19: =TRIM(SUBSTITUTE(SUBSTITUTE(OFFSET($Q19,0,COLUMN()-COLUMN($AL$1)),CHAR(160)," "),_xludf.UNICHAR(8239)," ")) -> #NAME? | AB19: =TRIM(SUBSTITUTE(SUBSTITUTE(OFFSET($Q19,0,COLUMN()-COLUMN($AL$1)),CHAR(160)," "),_xludf.UNICHAR(8239)," ")) -> #NAME? | AC19: =TRIM(SUBSTITUTE(SUBSTITUTE(OFFSET($Q19,0,COLUMN()-COLUMN($AL$1)),CHAR(160)," "),_xludf.UNICHAR(8239)," ")) -> #NAME? | AD19: =IF($E19="",0,--(COUNTIFS($E:$E,$E19,$C:$C,">"&$C19)+COUNTIFS($E$8:E19,$E19,$C$8:C19,$C19)=1)) -> 1 | AE19: =IF($C19="","",TEXT($C19,"yyyy-mm")) -> 2026-04 | AF19: =IF(OR($E19="",$AE19=""),0,IF(COUNTIFS($E$8:E19,$E19,$AE$8:AE19,$AE19)=1,1,0)) -> 1 | AG19: =IF($E19="",0,IF(COUNTIF($E$8:E19,$E19)=1,1,0)) -> 1
A20: 13 | B20: علي احمد سعيد الدوسيقي | C20: 2026-04-26 | E20: 470316779 | F20: 2025-01-27 | G20: 1 | H20: 0-5 | I20: Male | J20: male | K20: 595304423 | L20: Alnussirat | M20: N/A | N20: No | P20: Displaced | Q20: FM- CD | X20: =IF(E20="","",UPPER(LEFT($C$3,1)&"-"&LEFT($C$4,1)&"-"&TEXT(ROW(B13),"000")&"-"&TEXT(C20,"dd-mm"))) -> --013-26-04 | Y20: =TRIM(SUBSTITUTE(SUBSTITUTE(OFFSET($Q20,0,COLUMN()-COLUMN($AL$1)),CHAR(160)," "),_xludf.UNICHAR(8239)," ")) -> #NAME? | Z20: =TRIM(SUBSTITUTE(SUBSTITUTE(OFFSET($Q20,0,COLUMN()-COLUMN($AL$1)),CHAR(160)," "),_xludf.UNICHAR(8239)," ")) -> #NAME? | AA20: =TRIM(SUBSTITUTE(SUBSTITUTE(OFFSET($Q20,0,COLUMN()-COLUMN($AL$1)),CHAR(160)," "),_xludf.UNICHAR(8239)," ")) -> #NAME? | AB20: =TRIM(SUBSTITUTE(SUBSTITUTE(OFFSET($Q20,0,COLUMN()-COLUMN($AL$1)),CHAR(160)," "),_xludf.UNICHAR(8239)," ")) -> #NAME? | AC20: =TRIM(SUBSTITUTE(SUBSTITUTE(OFFSET($Q20,0,COLUMN()-COLUMN($AL$1)),CHAR(160)," "),_xludf.UNICHAR(8239)," ")) -> #NAME? | AD20: =IF($E20="",0,--(COUNTIFS($E:$E,$E20,$C:$C,">"&$C20)+COUNTIFS($E$8:E20,$E20,$C$8:C20,$C20)=1)) -> 1 | AE20: =IF($C20="","",TEXT($C20,"yyyy-mm")) -> 2026-04 | AF20: =IF(OR($E20="",$AE20=""),0,IF(COUNTIFS($E$8:E20,$E20,$AE$8:AE20,$AE20)=1,1,0)) -> 1 | AG20: =IF($E20="",0,IF(COUNTIF($E$8:E20,$E20)=1,1,0)) -> 1
A21: 14 | B21: شادي طارق يحيى ابو خاطر | C21: 2026-04-26 | E21: 470701152 | F21: 2025-08-01 | G21: 1 | H21: 0-5 | I21: Male | J21: male | K21: 597059290 | L21: Alnussirat | M21: N/A | N21: No | P21: Displaced | Q21: FM- CD | X21: =IF(E21="","",UPPER(LEFT($C$3,1)&"-"&LEFT($C$4,1)&"-"&TEXT(ROW(B14),"000")&"-"&TEXT(C21,"dd-mm"))) -> --014-26-04 | Y21: =TRIM(SUBSTITUTE(SUBSTITUTE(OFFSET($Q21,0,COLUMN()-COLUMN($AL$1)),CHAR(160)," "),_xludf.UNICHAR(8239)," ")) -> #NAME? | Z21: =TRIM(SUBSTITUTE(SUBSTITUTE(OFFSET($Q21,0,COLUMN()-COLUMN($AL$1)),CHAR(160)," "),_xludf.UNICHAR(8239)," ")) -> #NAME? | AA21: =TRIM(SUBSTITUTE(SUBSTITUTE(OFFSET($Q21,0,COLUMN()-COLUMN($AL$1)),CHAR(160)," "),_xludf.UNICHAR(8239)," ")) -> #NAME? | AB21: =TRIM(SUBSTITUTE(SUBSTITUTE(OFFSET($Q21,0,COLUMN()-COLUMN($AL$1)),CHAR(160)," "),_xludf.UNICHAR(8239)," ")) -> #NAME? | AC21: =TRIM(SUBSTITUTE(SUBSTITUTE(OFFSET($Q21,0,COLUMN()-COLUMN($AL$1)),CHAR(160)," "),_xludf.UNICHAR(8239)," ")) -> #NAME? | AD21: =IF($E21="",0,--(COUNTIFS($E:$E,$E21,$C:$C,">"&$C21)+COUNTIFS($E$8:E21,$E21,$C$8:C21,$C21)=1)) -> 1 | AE21: =IF($C21="","",TEXT($C21,"yyyy-mm")) -> 2026-04 | AF21: =IF(OR($E21="",$AE21=""),0,IF(COUNTIFS($E$8:E21,$E21,$AE$8:AE21,$AE21)=1,1,0)) -> 1 | AG21: =IF($E21="",0,IF(COUNTIF($E$8:E21,$E21)=1,1,0)) -> 1
A22: 15 | B22: محمد طارق يحيى ابو خاطر | C22: 2026-04-26 | E22: 446166944 | F22: 2024-03-19 | G22: 2 | H22: 0-5 | I22: Male | J22: male | K22: 595324423 | L22: Alnussirat | M22: N/A | N22: No | P22: Displaced | Q22: FM- CD | X22: =IF(E22="","",UPPER(LEFT($C$3,1)&"-"&LEFT($C$4,1)&"-"&TEXT(ROW(B15),"000")&"-"&TEXT(C22,"dd-mm"))) -> --015-26-04 | Y22: =TRIM(SUBSTITUTE(SUBSTITUTE(OFFSET($Q22,0,COLUMN()-COLUMN($AL$1)),CHAR(160)," "),_xludf.UNICHAR(8239)," ")) -> #NAME? | Z22: =TRIM(SUBSTITUTE(SUBSTITUTE(OFFSET($Q22,0,COLUMN()-COLUMN($AL$1)),CHAR(160)," "),_xludf.UNICHAR(8239)," ")) -> #NAME? | AA22: =TRIM(SUBSTITUTE(SUBSTITUTE(OFFSET($Q22,0,COLUMN()-COLUMN($AL$1)),CHAR(160)," "),_xludf.UNICHAR(8239)," ")) -> #NAME? | AB22: =TRIM(SUBSTITUTE(SUBSTITUTE(OFFSET($Q22,0,COLUMN()-COLUMN($AL$1)),CHAR(160)," "),_xludf.UNICHAR(8239)," ")) -> #NAME? | AC22: =TRIM(SUBSTITUTE(SUBSTITUTE(OFFSET($Q22,0,COLUMN()-COLUMN($AL$1)),CHAR(160)," "),_xludf.UNICHAR(8239)," ")) -> #NAME? | AD22: =IF($E22="",0,--(COUNTIFS($E:$E,$E22,$C:$C,">"&$C22)+COUNTIFS($E$8:E22,$E22,$C$8:C22,$C22)=1)) -> 1 | AE22: =IF($C22="","",TEXT($C22,"yyyy-mm")) -> 2026-04 | AF22: =IF(OR($E22="",$AE22=""),0,IF(COUNTIFS($E$8:E22,$E22,$AE$8:AE22,$AE22)=1,1,0)) -> 1 | AG22: =IF($E22="",0,IF(COUNTIF($E$8:E22,$E22)=1,1,0)) -> 1
A23: 16 | B23: محمد مهند محمد عطوة | C23: 2026-04-26 | E23: 445399918 | F23: 2021-07-11 | G23: 4 | H23: 0-5 | I23: Female | J23: female | K23: 593427538 | L23: Alnussirat | M23: N/A | N23: No | P23: Displaced | Q23: FM- NCD | X23: =IF(E23="","",UPPER(LEFT($C$3,1)&"-"&LEFT($C$4,1)&"-"&TEXT(ROW(B16),"000")&"-"&TEXT(C23,"dd-mm"))) -> --016-26-04 | Y23: =TRIM(SUBSTITUTE(SUBSTITUTE(OFFSET($Q23,0,COLUMN()-COLUMN($AL$1)),CHAR(160)," "),_xludf.UNICHAR(8239)," ")) -> #NAME? | Z23: =TRIM(SUBSTITUTE(SUBSTITUTE(OFFSET($Q23,0,COLUMN()-COLUMN($AL$1)),CHAR(160)," "),_xludf.UNICHAR(8239)," ")) -> #NAME? | AA23: =TRIM(SUBSTITUTE(SUBSTITUTE(OFFSET($Q23,0,COLUMN()-COLUMN($AL$1)),CHAR(160)," "),_xludf.UNICHAR(8239)," ")) -> #NAME? | AB23: =TRIM(SUBSTITUTE(SUBSTITUTE(OFFSET($Q23,0,COLUMN()-COLUMN($AL$1)),CHAR(160)," "),_xludf.UNICHAR(8239)," ")) -> #NAME? | AC23: =TRIM(SUBSTITUTE(SUBSTITUTE(OFFSET($Q23,0,COLUMN()-COLUMN($AL$1)),CHAR(160)," "),_xludf.UNICHAR(8239)," ")) -> #NAME? | AD23: =IF($E23="",0,--(COUNTIFS($E:$E,$E23,$C:$C,">"&$C23)+COUNTIFS($E$8:E23,$E23,$C$8:C23,$C23)=1)) -> 1 | AE23: =IF($C23="","",TEXT($C23,"yyyy-mm")) -> 2026-04 | AF23: =IF(OR($E23="",$AE23=""),0,IF(COUNTIFS($E$8:E23,$E23,$AE$8:AE23,$AE23)=1,1,0)) -> 1 | AG23: =IF($E23="",0,IF(COUNTIF($E$8:E23,$E23)=1,1,0)) -> 1
A24: 17 | B24: منى محمد دانيال أبو قمر | C24: 2026-04-26 | E24: 445426281 | F24: 2022-04-10 | G24: 4 | H24: 0-5 | I24: Female | J24: female | K24: 599573203 | L24: Alnussirat | M24: N/A | N24: No | P24: Displaced | Q24: FM- CD | X24: =IF(E24="","",UPPER(LEFT($C$3,1)&"-"&LEFT($C$4,1)&"-"&TEXT(ROW(B17),"000")&"-"&TEXT(C24,"dd-mm"))) -> --017-26-04 | Y24: =TRIM(SUBSTITUTE(SUBSTITUTE(OFFSET($Q24,0,COLUMN()-COLUMN($AL$1)),CHAR(160)," "),_xludf.UNICHAR(8239)," ")) -> #NAME? | Z24: =TRIM(SUBSTITUTE(SUBSTITUTE(OFFSET($Q24,0,COLUMN()-COLUMN($AL$1)),CHAR(160)," "),_xludf.UNICHAR(8239)," ")) -> #NAME? | AA24: =TRIM(SUBSTITUTE(SUBSTITUTE(OFFSET($Q24,0,COLUMN()-COLUMN($AL$1)),CHAR(160)," "),_xludf.UNICHAR(8239)," ")) -> #NAME? | AB24: =TRIM(SUBSTITUTE(SUBSTITUTE(OFFSET($Q24,0,COLUMN()-COLUMN($AL$1)),CHAR(160)," "),_xludf.UNICHAR(8239)," ")) -> #NAME? | AC24: =TRIM(SUBSTITUTE(SUBSTITUTE(OFFSET($Q24,0,COLUMN()-COLUMN($AL$1)),CHAR(160)," "),_xludf.UNICHAR(8239)," ")) -> #NAME? | AD24: =IF($E24="",0,--(COUNTIFS($E:$E,$E24,$C:$C,">"&$C24)+COUNTIFS($E$8:E24,$E24,$C$8:C24,$C24)=1)) -> 1 | AE24: =IF($C24="","",TEXT($C24,"yyyy-mm")) -> 2026-04 | AF24: =IF(OR($E24="",$AE24=""),0,IF(COUNTIFS($E$8:E24,$E24,$AE$8:AE24,$AE24)=1,1,0)) -> 1 | AG24: =IF($E24="",0,IF(COUNTIF($E$8:E24,$E24)=1,1,0)) -> 1
A25: 18 | B25: خميس يحيى احمد ابو خاطر | C25: 2026-04-26 | E25: 400823901 | F25: 1995-10-21 | G25: 30 | H25: 19-60 | I25: Female | J25: female | K25: 592200830 | L25: Alnussirat | M25: N/A | N25: No | P25: Displaced | Q25: FM- CD | X25: =IF(E25="","",UPPER(LEFT($C$3,1)&"-"&LEFT($C$4,1)&"-"&TEXT(ROW(B18),"000")&"-"&TEXT(C25,"dd-mm"))) -> --018-26-04 | Y25: =TRIM(SUBSTITUTE(SUBSTITUTE(OFFSET($Q25,0,COLUMN()-COLUMN($AL$1)),CHAR(160)," "),_xludf.UNICHAR(8239)," ")) -> #NAME? | Z25: =TRIM(SUBSTITUTE(SUBSTITUTE(OFFSET($Q25,0,COLUMN()-COLUMN($AL$1)),CHAR(160)," "),_xludf.UNICHAR(8239)," ")) -> #NAME? | AA25: =TRIM(SUBSTITUTE(SUBSTITUTE(OFFSET($Q25,0,COLUMN()-COLUMN($AL$1)),CHAR(160)," "),_xludf.UNICHAR(8239)," ")) -> #NAME? | AB25: =TRIM(SUBSTITUTE(SUBSTITUTE(OFFSET($Q25,0,COLUMN()-COLUMN($AL$1)),CHAR(160)," "),_xludf.UNICHAR(8239)," ")) -> #NAME? | AC25: =TRIM(SUBSTITUTE(SUBSTITUTE(OFFSET($Q25,0,COLUMN()-COLUMN($AL$1)),CHAR(160)," "),_xludf.UNICHAR(8239)," ")) -> #NAME? | AD25: =IF($E25="",0,--(COUNTIFS($E:$E,$E25,$C:$C,">"&$C25)+COUNTIFS($E$8:E25,$E25,$C$8:C25,$C25)=1)) -> 1 | AE25: =IF($C25="","",TEXT($C25,"yyyy-mm")) -> 2026-04 | AF25: =IF(OR($E25="",$AE25=""),0,IF(COUNTIFS($E$8:E25,$E25,$AE$8:AE25,$AE25)=1,1,0)) -> 1 | AG25: =IF($E25="",0,IF(COUNTIF($E$8:E25,$E25)=1,1,0)) -> 1
A26: 19 | B26: هبة كمال ابراهيم الحواجري | C26: 2026-04-26 | E26: 800015604 | F26: 1983-08-04 | G26: 42 | H26: 19-60 | I26: Female | J26: female | K26: 597413610 | L26: Alnussirat | M26: Married | N26: No | P26: Displaced | R26: GYN | X26: =IF(E26="","",UPPER(LEFT($C$3,1)&"-"&LEFT($C$4,1)&"-"&TEXT(ROW(B19),"000")&"-"&TEXT(C26,"dd-mm"))) -> --019-26-04 | Y26: =TRIM(SUBSTITUTE(SUBSTITUTE(OFFSET($Q26,0,COLUMN()-COLUMN($AL$1)),CHAR(160)," "),_xludf.UNICHAR(8239)," ")) -> #NAME? | Z26: =TRIM(SUBSTITUTE(SUBSTITUTE(OFFSET($Q26,0,COLUMN()-COLUMN($AL$1)),CHAR(160)," "),_xludf.UNICHAR(8239)," ")) -> #NAME? | AA26: =TRIM(SUBSTITUTE(SUBSTITUTE(OFFSET($Q26,0,COLUMN()-COLUMN($AL$1)),CHAR(160)," "),_xludf.UNICHAR(8239)," ")) -> #NAME? | AB26: =TRIM(SUBSTITUTE(SUBSTITUTE(OFFSET($Q26,0,COLUMN()-COLUMN($AL$1)),CHAR(160)," "),_xludf.UNICHAR(8239)," ")) -> #NAME? | AC26: =TRIM(SUBSTITUTE(SUBSTITUTE(OFFSET($Q26,0,COLUMN()-COLUMN($AL$1)),CHAR(160)," "),_xludf.UNICHAR(8239)," ")) -> #NAME? | AD26: =IF($E26="",0,--(COUNTIFS($E:$E,$E26,$C:$C,">"&$C26)+COUNTIFS($E$8:E26,$E26,$C$8:C26,$C26)=1)) -> 1 | AE26: =IF($C26="","",TEXT($C26,"yyyy-mm")) -> 2026-04 | AF26: =IF(OR($E26="",$AE26=""),0,IF(COUNTIFS($E$8:E26,$E26,$AE$8:AE26,$AE26)=1,1,0)) -> 1 | AG26: =IF($E26="",0,IF(COUNTIF($E$8:E26,$E26)=1,1,0)) -> 1
A27: 20 | B27: سيدرا سامي شفيق النواجحة | C27: 2026-04-26 | E27: 456702083 | F27: 2003-04-26 | G27: 23 | H27: 19-60 | I27: Female | J27: female | K27: 598194042 | L27: Alnussirat | M27: Married | N27: No | P27: Displaced | S27: Follow-up Dressing | X27: =IF(E27="","",UPPER(LEFT($C$3,1)&"-"&LEFT($C$4,1)&"-"&TEXT(ROW(B20),"000")&"-"&TEXT(C27,"dd-mm"))) -> --020-26-04 | Y27: =TRIM(SUBSTITUTE(SUBSTITUTE(OFFSET($Q27,0,COLUMN()-COLUMN($AL$1)),CHAR(160)," "),_xludf.UNICHAR(8239)," ")) -> #NAME? | Z27: =TRIM(SUBSTITUTE(SUBSTITUTE(OFFSET($Q27,0,COLUMN()-COLUMN($AL$1)),CHAR(160)," "),_xludf.UNICHAR(8239)," ")) -> #NAME? | AA27: =TRIM(SUBSTITUTE(SUBSTITUTE(OFFSET($Q27,0,COLUMN()-COLUMN($AL$1)),CHAR(160)," "),_xludf.UNICHAR(8239)," ")) -> #NAME? | AB27: =TRIM(SUBSTITUTE(SUBSTITUTE(OFFSET($Q27,0,COLUMN()-COLUMN($AL$1)),CHAR(160)," "),_xludf.UNICHAR(8239)," ")) -> #NAME? | AC27: =TRIM(SUBSTITUTE(SUBSTITUTE(OFFSET($Q27,0,COLUMN()-COLUMN($AL$1)),CHAR(160)," "),_xludf.UNICHAR(8239)," ")) -> #NAME? | AD27: =IF($E27="",0,--(COUNTIFS($E:$E,$E27,$C:$C,">"&$C27)+COUNTIFS($E$8:E27,$E27,$C$8:C27,$C27)=1)) -> 1 | AE27: =IF($C27="","",TEXT($C27,"yyyy-mm")) -> 2026-04 | AF27: =IF(OR($E27="",$AE27=""),0,IF(COUNTIFS($E$8:E27,$E27,$AE$8:AE27,$AE27)=1,1,0)) -> 1 | AG27: =IF($E27="",0,IF(COUNTIF($E$8:E27,$E27)=1,1,0)) -> 1
A28: 21 | B28: ريتاج رامي محمود الحواجري | C28: 2026-04-26 | E28: 445166929 | F28: 2024-01-23 | G28: 2 | H28: 0-5 | I28: Female | J28: female | K28: 597413610 | L28: Alnussirat | M28: N/A | N28: No | P28: Displaced | Q28: FM- CD | X28: =IF(E28="","",UPPER(LEFT($C$3,1)&"-"&LEFT($C$4,1)&"-"&TEXT(ROW(B21),"000")&"-"&TEXT(C28,"dd-mm"))) -> --021-26-04 | Y28: =TRIM(SUBSTITUTE(SUBSTITUTE(OFFSET($Q28,0,COLUMN()-COLUMN($AL$1)),CHAR(160)," "),_xludf.UNICHAR(8239)," ")) -> #NAME? | Z28: =TRIM(SUBSTITUTE(SUBSTITUTE(OFFSET($Q28,0,COLUMN()-COLUMN($AL$1)),CHAR(160)," "),_xludf.UNICHAR(8239)," ")) -> #NAME? | AA28: =TRIM(SUBSTITUTE(SUBSTITUTE(OFFSET($Q28,0,COLUMN()-COLUMN($AL$1)),CHAR(160)," "),_xludf.UNICHAR(8239)," ")) -> #NAME? | AB28: =TRIM(SUBSTITUTE(SUBSTITUTE(OFFSET($Q28,0,COLUMN()-COLUMN($AL$1)),CHAR(160)," "),_xludf.UNICHAR(8239)," ")) -> #NAME? | AC28: =TRIM(SUBSTITUTE(SUBSTITUTE(OFFSET($Q28,0,COLUMN()-COLUMN($AL$1)),CHAR(160)," "),_xludf.UNICHAR(8239)," ")) -> #NAME? | AD28: =IF($E28="",0,--(COUNTIFS($E:$E,$E28,$C:$C,">"&$C28)+COUNTIFS($E$8:E28,$E28,$C$8:C28,$C28)=1)) -> 1 | AE28: =IF($C28="","",TEXT($C28,"yyyy-mm")) -> 2026-04 | AF28: =IF(OR($E28="",$AE28=""),0,IF(COUNTIFS($E$8:E28,$E28,$AE$8:AE28,$AE28)=1,1,0)) -> 1 | AG28: =IF($E28="",0,IF(COUNTIF($E$8:E28,$E28)=1,1,0)) -> 1
A29: 22 | B29: ايلاف خليل رشيد القاضي | C29: 2026-04-26 | E29: 438470148 | F29: 2017-10-25 | G29: 8 | H29: 6-18 | I29: Female | J29: female | K29: 597337087 | L29: Alnussirat | M29: N/A | N29: No | P29: Displaced | Q29: FM- NCD | X29: =IF(E29="","",UPPER(LEFT($C$3,1)&"-"&LEFT($C$4,1)&"-"&TEXT(ROW(B22),"000")&"-"&TEXT(C29,"dd-mm"))) -> --022-26-04 | Y29: =TRIM(SUBSTITUTE(SUBSTITUTE(OFFSET($Q29,0,COLUMN()-COLUMN($AL$1)),CHAR(160)," "),_xludf.UNICHAR(8239)," ")) -> #NAME? | Z29: =TRIM(SUBSTITUTE(SUBSTITUTE(OFFSET($Q29,0,COLUMN()-COLUMN($AL$1)),CHAR(160)," "),_xludf.UNICHAR(8239)," ")) -> #NAME? | AA29: =TRIM(SUBSTITUTE(SUBSTITUTE(OFFSET($Q29,0,COLUMN()-COLUMN($AL$1)),CHAR(160)," "),_xludf.UNICHAR(8239)," ")) -> #NAME? | AB29: =TRIM(SUBSTITUTE(SUBSTITUTE(OFFSET($Q29,0,COLUMN()-COLUMN($AL$1)),CHAR(160)," "),_xludf.UNICHAR(8239)," ")) -> #NAME? | AC29: =TRIM(SUBSTITUTE(SUBSTITUTE(OFFSET($Q29,0,COLUMN()-COLUMN($AL$1)),CHAR(160)," "),_xludf.UNICHAR(8239)," ")) -> #NAME? | AD29: =IF($E29="",0,--(COUNTIFS($E:$E,$E29,$C:$C,">"&$C29)+COUNTIFS($E$8:E29,$E29,$C$8:C29,$C29)=1)) -> 1 | AE29: =IF($C29="","",TEXT($C29,"yyyy-mm")) -> 2026-04 | AF29: =IF(OR($E29="",$AE29=""),0,IF(COUNTIFS($E$8:E29,$E29,$AE$8:AE29,$AE29)=1,1,0)) -> 1 | AG29: =IF($E29="",0,IF(COUNTIF($E$8:E29,$E29)=1,1,0)) -> 1
A30: 23 | B30: سحر خضر محمود المجدلاوي | C30: 2026-04-26 | E30: 803459551 | F30: 1994-02-02 | G30: 32 | H30: 19-60 | I30: Female | J30: female | K30: 599619239 | L30: Alnussirat | M30: Married | N30: No | P30: Displaced | R30: ANC | U30: Screening | X30: =IF(E30="","",UPPER(LEFT($C$3,1)&"-"&LEFT($C$4,1)&"-"&TEXT(ROW(B23),"000")&"-"&TEXT(C30,"dd-mm"))) -> --023-26-04 | Y30: =TRIM(SUBSTITUTE(SUBSTITUTE(OFFSET($Q30,0,COLUMN()-COLUMN($AL$1)),CHAR(160)," "),_xludf.UNICHAR(8239)," ")) -> #NAME? | Z30: =TRIM(SUBSTITUTE(SUBSTITUTE(OFFSET($Q30,0,COLUMN()-COLUMN($AL$1)),CHAR(160)," "),_xludf.UNICHAR(8239)," ")) -> #NAME? | AA30: =TRIM(SUBSTITUTE(SUBSTITUTE(OFFSET($Q30,0,COLUMN()-COLUMN($AL$1)),CHAR(160)," "),_xludf.UNICHAR(8239)," ")) -> #NAME? | AB30: =TRIM(SUBSTITUTE(SUBSTITUTE(OFFSET($Q30,0,COLUMN()-COLUMN($AL$1)),CHAR(160)," "),_xludf.UNICHAR(8239)," ")) -> #NAME? | AC30: =TRIM(SUBSTITUTE(SUBSTITUTE(OFFSET($Q30,0,COLUMN()-COLUMN($AL$1)),CHAR(160)," "),_xludf.UNICHAR(8239)," ")) -> #NAME? | AD30: =IF($E30="",0,--(COUNTIFS($E:$E,$E30,$C:$C,">"&$C30)+COUNTIFS($E$8:E30,$E30,$C$8:C30,$C30)=1)) -> 1 | AE30: =IF($C30="","",TEXT($C30,"yyyy-mm")) -> 2026-04 | AF30: =IF(OR($E30="",$AE30=""),0,IF(COUNTIFS($E$8:E30,$E30,$AE$8:AE30,$AE30)=1,1,0)) -> 1 | AG30: =IF($E30="",0,IF(COUNTIF($E$8:E30,$E30)=1,1,0)) -> 1
A31: 24 | B31: منى هشام عبد القادر عبد القادر | C31: 2026-04-26 | E31: 400947206 | F31: 1996-08-02 | G31: 29 | H31: 19-60 | I31: Female | J31: female | K31: 592123364 | L31: Alnussirat | M31: N/A | N31: No | P31: Displaced | R31: ANC | U31: Screening | X31: =IF(E31="","",UPPER(LEFT($C$3,1)&"-"&LEFT($C$4,1)&"-"&TEXT(ROW(B24),"000")&"-"&TEXT(C31,"dd-mm"))) -> --024-26-04 | Y31: =TRIM(SUBSTITUTE(SUBSTITUTE(OFFSET($Q31,0,COLUMN()-COLUMN($AL$1)),CHAR(160)," "),_xludf.UNICHAR(8239)," ")) -> #NAME? | Z31: =TRIM(SUBSTITUTE(SUBSTITUTE(OFFSET($Q31,0,COLUMN()-COLUMN($AL$1)),CHAR(160)," "),_xludf.UNICHAR(8239)," ")) -> #NAME? | AA31: =TRIM(SUBSTITUTE(SUBSTITUTE(OFFSET($Q31,0,COLUMN()-COLUMN($AL$1)),CHAR(160)," "),_xludf.UNICHAR(8239)," ")) -> #NAME? | AB31: =TRIM(SUBSTITUTE(SUBSTITUTE(OFFSET($Q31,0,COLUMN()-COLUMN($AL$1)),CHAR(160)," "),_xludf.UNICHAR(8239)," ")) -> #NAME? | AC31: =TRIM(SUBSTITUTE(SUBSTITUTE(OFFSET($Q31,0,COLUMN()-COLUMN($AL$1)),CHAR(160)," "),_xludf.UNICHAR(8239)," ")) -> #NAME? | AD31: =IF($E31="",0,--(COUNTIFS($E:$E,$E31,$C:$C,">"&$C31)+COUNTIFS($E$8:E31,$E31,$C$8:C31,$C31)=1)) -> 1 | AE31: =IF($C31="","",TEXT($C31,"yyyy-mm")) -> 2026-04 | AF31: =IF(OR($E31="",$AE31=""),0,IF(COUNTIFS($E$8:E31,$E31,$AE$8:AE31,$AE31)=1,1,0)) -> 1 | AG31: =IF($E31="",0,IF(COUNTIF($E$8:E31,$E31)=1,1,0)) -> 1
A32: 25 | B32: محمد نضال ناهض عطالله | C32: 2026-04-26 | E32: 470291717 | F32: 2024-07-24 | G32: 1 | H32: 0-5 | I32: Male | J32: male | K32: 597825458 | L32: Alnussirat | M32: N/A | N32: No | P32: Displaced | Q32: FM- CD | X32: =IF(E32="","",UPPER(LEFT($C$3,1)&"-"&LEFT($C$4,1)&"-"&TEXT(ROW(B25),"000")&"-"&TEXT(C32,"dd-mm"))) -> --025-26-04 | Y32: =TRIM(SUBSTITUTE(SUBSTITUTE(OFFSET($Q32,0,COLUMN()-COLUMN($AL$1)),CHAR(160)," "),_xludf.UNICHAR(8239)," ")) -> #NAME? | Z32: =TRIM(SUBSTITUTE(SUBSTITUTE(OFFSET($Q32,0,COLUMN()-COLUMN($AL$1)),CHAR(160)," "),_xludf.UNICHAR(8239)," ")) -> #NAME? | AA32: =TRIM(SUBSTITUTE(SUBSTITUTE(OFFSET($Q32,0,COLUMN()-COLUMN($AL$1)),CHAR(160)," "),_xludf.UNICHAR(8239)," ")) -> #NAME? | AB32: =TRIM(SUBSTITUTE(SUBSTITUTE(OFFSET($Q32,0,COLUMN()-COLUMN($AL$1)),CHAR(160)," "),_xludf.UNICHAR(8239)," ")) -> #NAME? | AC32: =TRIM(SUBSTITUTE(SUBSTITUTE(OFFSET($Q32,0,COLUMN()-COLUMN($AL$1)),CHAR(160)," "),_xludf.UNICHAR(8239)," ")) -> #NAME? | AD32: =IF($E32="",0,--(COUNTIFS($E:$E,$E32,$C:$C,">"&$C32)+COUNTIFS($E$8:E32,$E32,$C$8:C32,$C32)=1)) -> 1 | AE32: =IF($C32="","",TEXT($C32,"yyyy-mm")) -> 2026-04 | AF32: =IF(OR($E32="",$AE32=""),0,IF(COUNTIFS($E$8:E32,$E32,$AE$8:AE32,$AE32)=1,1,0)) -> 1 | AG32: =IF($E32="",0,IF(COUNTIF($E$8:E32,$E32)=1,1,0)) -> 1
A33: 26 | B33: انور نضال ناهض عطالله | C33: 2026-04-26 | E33: 470598533 | F33: 2025-10-13 | G33: 1 | H33: 0-5 | I33: Male | J33: male | K33: 597825458 | L33: Alnussirat | M33: N/A | N33: No | P33: Displaced | Q33: FM- CD | X33: =IF(E33="","",UPPER(LEFT($C$3,1)&"-"&LEFT($C$4,1)&"-"&TEXT(ROW(B26),"000")&"-"&TEXT(C33,"dd-mm"))) -> --026-26-04 | Y33: =TRIM(SUBSTITUTE(SUBSTITUTE(OFFSET($Q33,0,COLUMN()-COLUMN($AL$1)),CHAR(160)," "),_xludf.UNICHAR(8239)," ")) -> #NAME? | Z33: =TRIM(SUBSTITUTE(SUBSTITUTE(OFFSET($Q33,0,COLUMN()-COLUMN($AL$1)),CHAR(160)," "),_xludf.UNICHAR(8239)," ")) -> #NAME? | AA33: =TRIM(SUBSTITUTE(SUBSTITUTE(OFFSET($Q33,0,COLUMN()-COLUMN($AL$1)),CHAR(160)," "),_xludf.UNICHAR(8239)," ")) -> #NAME? | AB33: =TRIM(SUBSTITUTE(SUBSTITUTE(OFFSET($Q33,0,COLUMN()-COLUMN($AL$1)),CHAR(160)," "),_xludf.UNICHAR(8239)," ")) -> #NAME? | AC33: =TRIM(SUBSTITUTE(SUBSTITUTE(OFFSET($Q33,0,COLUMN()-COLUMN($AL$1)),CHAR(160)," "),_xludf.UNICHAR(8239)," ")) -> #NAME? | AD33: =IF($E33="",0,--(COUNTIFS($E:$E,$E33,$C:$C,">"&$C33)+COUNTIFS($E$8:E33,$E33,$C$8:C33,$C33)=1)) -> 1 | AE33: =IF($C33="","",TEXT($C33,"yyyy-mm")) -> 2026-04 | AF33: =IF(OR($E33="",$AE33=""),0,IF(COUNTIFS($E$8:E33,$E33,$AE$8:AE33,$AE33)=1,1,0)) -> 1 | AG33: =IF($E33="",0,IF(COUNTIF($E$8:E33,$E33)=1,1,0)) -> 1
A34: 27 | B34: اسراء شوقي عايش ابو عطالله | C34: 2026-04-26 | E34: 406160846 | F34: 2001-07-12 | G34: 24 | H34: 19-60 | I34: Female | J34: female | K34: 592236933 | L34: Alnussirat | M34: Married | N34: No | P34: Displaced | R34: ANC | U34: Screening | X34: =IF(E34="","",UPPER(LEFT($C$3,1)&"-"&LEFT($C$4,1)&"-"&TEXT(ROW(B27),"000")&"-"&TEXT(C34,"dd-mm"))) -> --027-26-04 | Y34: =TRIM(SUBSTITUTE(SUBSTITUTE(OFFSET($Q34,0,COLUMN()-COLUMN($AL$1)),CHAR(160)," "),_xludf.UNICHAR(8239)," ")) -> #NAME? | Z34: =TRIM(SUBSTITUTE(SUBSTITUTE(OFFSET($Q34,0,COLUMN()-COLUMN($AL$1)),CHAR(160)," "),_xludf.UNICHAR(8239)," ")) -> #NAME? | AA34: =TRIM(SUBSTITUTE(SUBSTITUTE(OFFSET($Q34,0,COLUMN()-COLUMN($AL$1)),CHAR(160)," "),_xludf.UNICHAR(8239)," ")) -> #NAME? | AB34: =TRIM(SUBSTITUTE(SUBSTITUTE(OFFSET($Q34,0,COLUMN()-COLUMN($AL$1)),CHAR(160)," "),_xludf.UNICHAR(8239)," ")) -> #NAME? | AC34: =TRIM(SUBSTITUTE(SUBSTITUTE(OFFSET($Q34,0,COLUMN()-COLUMN($AL$1)),CHAR(160)," "),_xludf.UNICHAR(8239)," ")) -> #NAME? | AD34: =IF($E34="",0,--(COUNTIFS($E:$E,$E34,$C:$C,">"&$C34)+COUNTIFS($E$8:E34,$E34,$C$8:C34,$C34)=1)) -> 1 | AE34: =IF($C34="","",TEXT($C34,"yyyy-mm")) -> 2026-04 | AF34: =IF(OR($E34="",$AE34=""),0,IF(COUNTIFS($E$8:E34,$E34,$AE$8:AE34,$AE34)=1,1,0)) -> 1 | AG34: =IF($E34="",0,IF(COUNTIF($E$8:E34,$E34)=1,1,0)) -> 1
A35: 28 | B35: هداية رمزي نصر عطالله | C35: 2026-04-26 | E35: 445916141 | F35: 2024-03-18 | G35: 2 | H35: 0-5 | I35: Female | J35: female | K35: 592236933 | L35: Alnussirat | M35: N/A | N35: No | P35: Displaced | Q35: FM- CD | X35: =IF(E35="","",UPPER(LEFT($C$3,1)&"-"&LEFT($C$4,1)&"-"&TEXT(ROW(B28),"000")&"-"&TEXT(C35,"dd-mm"))) -> --028-26-04 | Y35: =TRIM(SUBSTITUTE(SUBSTITUTE(OFFSET($Q35,0,COLUMN()-COLUMN($AL$1)),CHAR(160)," "),_xludf.UNICHAR(8239)," ")) -> #NAME? | Z35: =TRIM(SUBSTITUTE(SUBSTITUTE(OFFSET($Q35,0,COLUMN()-COLUMN($AL$1)),CHAR(160)," "),_xludf.UNICHAR(8239)," ")) -> #NAME? | AA35: =TRIM(SUBSTITUTE(SUBSTITUTE(OFFSET($Q35,0,COLUMN()-COLUMN($AL$1)),CHAR(160)," "),_xludf.UNICHAR(8239)," ")) -> #NAME? | AB35: =TRIM(SUBSTITUTE(SUBSTITUTE(OFFSET($Q35,0,COLUMN()-COLUMN($AL$1)),CHAR(160)," "),_xludf.UNICHAR(8239)," ")) -> #NAME? | AC35: =TRIM(SUBSTITUTE(SUBSTITUTE(OFFSET($Q35,0,COLUMN()-COLUMN($AL$1)),CHAR(160)," "),_xludf.UNICHAR(8239)," ")) -> #NAME? | AD35: =IF($E35="",0,--(COUNTIFS($E:$E,$E35,$C:$C,">"&$C35)+COUNTIFS($E$8:E35,$E35,$C$8:C35,$C35)=1)) -> 1 | AE35: =IF($C35="","",TEXT($C35,"yyyy-mm")) -> 2026-04 | AF35: =IF(OR($E35="",$AE35=""),0,IF(COUNTIFS($E$8:E35,$E35,$AE$8:AE35,$AE35)=1,1,0)) -> 1 | AG35: =IF($E35="",0,IF(COUNTIF($E$8:E35,$E35)=1,1,0)) -> 1
A36: 29 | B36: ريم خليل ابراهيم حسين | C36: 2026-04-26 | E36: 905451522 | F36: 1980-01-13 | G36: 46 | H36: 19-60 | I36: Female | J36: female | K36: 598728701 | L36: Alnussirat | M36: N/A | N36: No | P36: Displaced | Q36: FM- CD | X36: =IF(E36="","",UPPER(LEFT($C$3,1)&"-"&LEFT($C$4,1)&"-"&TEXT(ROW(B29),"000")&"-"&TEXT(C36,"dd-mm"))) -> --029-26-04 | Y36: =TRIM(SUBSTITUTE(SUBSTITUTE(OFFSET($Q36,0,COLUMN()-COLUMN($AL$1)),CHAR(160)," "),_xludf.UNICHAR(8239)," ")) -> #NAME? | Z36: =TRIM(SUBSTITUTE(SUBSTITUTE(OFFSET($Q36,0,COLUMN()-COLUMN($AL$1)),CHAR(160)," "),_xludf.UNICHAR(8239)," ")) -> #NAME? | AA36: =TRIM(SUBSTITUTE(SUBSTITUTE(OFFSET($Q36,0,COLUMN()-COLUMN($AL$1)),CHAR(160)," "),_xludf.UNICHAR(8239)," ")) -> #NAME? | AB36: =TRIM(SUBSTITUTE(SUBSTITUTE(OFFSET($Q36,0,COLUMN()-COLUMN($AL$1)),CHAR(160)," "),_xludf.UNICHAR(8239)," ")) -> #NAME? | AC36: =TRIM(SUBSTITUTE(SUBSTITUTE(OFFSET($Q36,0,COLUMN()-COLUMN($AL$1)),CHAR(160)," "),_xludf.UNICHAR(8239)," ")) -> #NAME? | AD36: =IF($E36="",0,--(COUNTIFS($E:$E,$E36,$C:$C,">"&$C36)+COUNTIFS($E$8:E36,$E36,$C$8:C36,$C36)=1)) -> 1 | AE36: =IF($C36="","",TEXT($C36,"yyyy-mm")) -> 2026-04 | AF36: =IF(OR($E36="",$AE36=""),0,IF(COUNTIFS($E$8:E36,$E36,$AE$8:AE36,$AE36)=1,1,0)) -> 1 | AG36: =IF($E36="",0,IF(COUNTIF($E$8:E36,$E36)=1,1,0)) -> 1
A37: 30 | B37: نعمة حسني محمد الخالدي | C37: 2026-04-26 | E37: 400905691 | F37: 1996-02-21 | G37: 30 | H37: 19-60 | I37: Female | J37: female | K37: 598184056 | L37: Alnussirat | M37: Married | N37: No | P37: Displaced | R37: FP | X37: =IF(E37="","",UPPER(LEFT($C$3,1)&"-"&LEFT($C$4,1)&"-"&TEXT(ROW(B30),"000")&"-"&TEXT(C37,"dd-mm"))) -> --030-26-04 | Y37: =TRIM(SUBSTITUTE(SUBSTITUTE(OFFSET($Q37,0,COLUMN()-COLUMN($AL$1)),CHAR(160)," "),_xludf.UNICHAR(8239)," ")) -> #NAME? | Z37: =TRIM(SUBSTITUTE(SUBSTITUTE(OFFSET($Q37,0,COLUMN()-COLUMN($AL$1)),CHAR(160)," "),_xludf.UNICHAR(8239)," ")) -> #NAME? | AA37: =TRIM(SUBSTITUTE(SUBSTITUTE(OFFSET($Q37,0,COLUMN()-COLUMN($AL$1)),CHAR(160)," "),_xludf.UNICHAR(8239)," ")) -> #NAME? | AB37: =TRIM(SUBSTITUTE(SUBSTITUTE(OFFSET($Q37,0,COLUMN()-COLUMN($AL$1)),CHAR(160)," "),_xludf.UNICHAR(8239)," ")) -> #NAME? | AC37: =TRIM(SUBSTITUTE(SUBSTITUTE(OFFSET($Q37,0,COLUMN()-COLUMN($AL$1)),CHAR(160)," "),_xludf.UNICHAR(8239)," ")) -> #NAME? | AD37: =IF($E37="",0,--(COUNTIFS($E:$E,$E37,$C:$C,">"&$C37)+COUNTIFS($E$8:E37,$E37,$C$8:C37,$C37)=1)) -> 1 | AE37: =IF($C37="","",TEXT($C37,"yyyy-mm")) -> 2026-04 | AF37: =IF(OR($E37="",$AE37=""),0,IF(COUNTIFS($E$8:E37,$E37,$AE$8:AE37,$AE37)=1,1,0)) -> 1 | AG37: =IF($E37="",0,IF(COUNTIF($E$8:E37,$E37)=1,1,0)) -> 1
A38: 31 | B38: اسماعيل محمد احمد الخالدي | C38: 2026-04-26 | E38: 445137664 | F38: 2022-03-07 | G38: 4 | H38: 0-5 | I38: Male | J38: male | K38: 598184056 | L38: Alnussirat | M38: N/A | N38: No | P38: Displaced | Q38: FM- CD | X38: =IF(E38="","",UPPER(LEFT($C$3,1)&"-"&LEFT($C$4,1)&"-"&TEXT(ROW(B31),"000")&"-"&TEXT(C38,"dd-mm"))) -> --031-26-04 | Y38: =TRIM(SUBSTITUTE(SUBSTITUTE(OFFSET($Q38,0,COLUMN()-COLUMN($AL$1)),CHAR(160)," "),_xludf.UNICHAR(8239)," ")) -> #NAME? | Z38: =TRIM(SUBSTITUTE(SUBSTITUTE(OFFSET($Q38,0,COLUMN()-COLUMN($AL$1)),CHAR(160)," "),_xludf.UNICHAR(8239)," ")) -> #NAME? | AA38: =TRIM(SUBSTITUTE(SUBSTITUTE(OFFSET($Q38,0,COLUMN()-COLUMN($AL$1)),CHAR(160)," "),_xludf.UNICHAR(8239)," ")) -> #NAME? | AB38: =TRIM(SUBSTITUTE(SUBSTITUTE(OFFSET($Q38,0,COLUMN()-COLUMN($AL$1)),CHAR(160)," "),_xludf.UNICHAR(8239)," ")) -> #NAME? | AC38: =TRIM(SUBSTITUTE(SUBSTITUTE(OFFSET($Q38,0,COLUMN()-COLUMN($AL$1)),CHAR(160)," "),_xludf.UNICHAR(8239)," ")) -> #NAME? | AD38: =IF($E38="",0,--(COUNTIFS($E:$E,$E38,$C:$C,">"&$C38)+COUNTIFS($E$8:E38,$E38,$C$8:C38,$C38)=1)) -> 1 | AE38: =IF($C38="","",TEXT($C38,"yyyy-mm")) -> 2026-04 | AF38: =IF(OR($E38="",$AE38=""),0,IF(COUNTIFS($E$8:E38,$E38,$AE$8:AE38,$AE38)=1,1,0)) -> 1 | AG38: =IF($E38="",0,IF(COUNTIF($E$8:E38,$E38)=1,1,0)) -> 1
A39: 32 | B39: محمدمحمد منير دويك | C39: 2026-04-26 | E39: 429836406 | F39: 2010-03-31 | G39: 16 | H39: 6-18 | I39: Female | J39: female | K39: 599860312 | L39: Alnussirat | M39: Single | N39: No | P39: Displaced | Q39: FM- CD | X39: =IF(E39="","",UPPER(LEFT($C$3,1)&"-"&LEFT($C$4,1)&"-"&TEXT(ROW(B32),"000")&"-"&TEXT(C39,"dd-mm"))) -> --032-26-04 | Y39: =TRIM(SUBSTITUTE(SUBSTITUTE(OFFSET($Q39,0,COLUMN()-COLUMN($AL$1)),CHAR(160)," "),_xludf.UNICHAR(8239)," ")) -> #NAME? | Z39: =TRIM(SUBSTITUTE(SUBSTITUTE(OFFSET($Q39,0,COLUMN()-COLUMN($AL$1)),CHAR(160)," "),_xludf.UNICHAR(8239)," ")) -> #NAME? | AA39: =TRIM(SUBSTITUTE(SUBSTITUTE(OFFSET($Q39,0,COLUMN()-COLUMN($AL$1)),CHAR(160)," "),_xludf.UNICHAR(8239)," ")) -> #NAME? | AB39: =TRIM(SUBSTITUTE(SUBSTITUTE(OFFSET($Q39,0,COLUMN()-COLUMN($AL$1)),CHAR(160)," "),_xludf.UNICHAR(8239)," ")) -> #NAME? | AC39: =TRIM(SUBSTITUTE(SUBSTITUTE(OFFSET($Q39,0,COLUMN()-COLUMN($AL$1)),CHAR(160)," "),_xludf.UNICHAR(8239)," ")) -> #NAME? | AD39: =IF($E39="",0,--(COUNTIFS($E:$E,$E39,$C:$C,">"&$C39)+COUNTIFS($E$8:E39,$E39,$C$8:C39,$C39)=1)) -> 1 | AE39: =IF($C39="","",TEXT($C39,"yyyy-mm")) -> 2026-04 | AF39: =IF(OR($E39="",$AE39=""),0,IF(COUNTIFS($E$8:E39,$E39,$AE$8:AE39,$AE39)=1,1,0)) -> 1 | AG39: =IF($E39="",0,IF(COUNTIF($E$8:E39,$E39)=1,1,0)) -> 1
A40: 33 | B40: ريم جميل احمد الزعانين | C40: 2026-04-26 | E40: 400650644 | F40: 1996-04-17 | G40: 30 | H40: 19-60 | I40: Female | J40: female | K40: 595901415 | M40: Married | N40: No | P40: Displaced | R40: ANC | U40: Screening | X40: =IF(E40="","",UPPER(LEFT($C$3,1)&"-"&LEFT($C$4,1)&"-"&TEXT(ROW(B33),"000")&"-"&TEXT(C40,"dd-mm"))) -> --033-26-04 | Y40: =TRIM(SUBSTITUTE(SUBSTITUTE(OFFSET($Q40,0,COLUMN()-COLUMN($AL$1)),CHAR(160)," "),_xludf.UNICHAR(8239)," ")) -> #NAME? | Z40: =TRIM(SUBSTITUTE(SUBSTITUTE(OFFSET($Q40,0,COLUMN()-COLUMN($AL$1)),CHAR(160)," "),_xludf.UNICHAR(8239)," ")) -> #NAME? | AA40: =TRIM(SUBSTITUTE(SUBSTITUTE(OFFSET($Q40,0,COLUMN()-COLUMN($AL$1)),CHAR(160)," "),_xludf.UNICHAR(8239)," ")) -> #NAME? | AB40: =TRIM(SUBSTITUTE(SUBSTITUTE(OFFSET($Q40,0,COLUMN()-COLUMN($AL$1)),CHAR(160)," "),_xludf.UNICHAR(8239)," ")) -> #NAME? | AC40: =TRIM(SUBSTITUTE(SUBSTITUTE(OFFSET($Q40,0,COLUMN()-COLUMN($AL$1)),CHAR(160)," "),_xludf.UNICHAR(8239)," ")) -> #NAME? | AD40: =IF($E40="",0,--(COUNTIFS($E:$E,$E40,$C:$C,">"&$C40)+COUNTIFS($E$8:E40,$E40,$C$8:C40,$C40)=1)) -> 1 | AE40: =IF($C40="","",TEXT($C40,"yyyy-mm")) -> 2026-04 | AF40: =IF(OR($E40="",$AE40=""),0,IF(COUNTIFS($E$8:E40,$E40,$AE$8:AE40,$AE40)=1,1,0)) -> 1 | AG40: =IF($E40="",0,IF(COUNTIF($E$8:E40,$E40)=1,1,0)) -> 1
...

Sheet Info
A1: FM services | B1: SRH Services | C1: Wound Care | D1: Breast Cancer | E1: Mal-Nutirion | F1: {=_xlws.FILTER(Info!$A$2:$A$14,Info!$A$2:$A$14<>"")} -> #NAME? | G1: {=_xlws.FILTER(Info!$B$2:$B$14,Info!$B$2:$B$14<>"")} -> #NAME? | H1: {=_xlws.FILTER(Info!$C$2:$C$14,Info!$C$2:$C$14<>"")} -> #NAME? | I1: {=_xlws.FILTER(Info!$D$2:$D$14,Info!$D$2:$D$14<>"")} -> #NAME? | J1: {=_xlws.FILTER(Info!$E$2:$E$14,Info!$E$2:$E$14<>"")} -> #NAME? | L1: Gender | N1: {=_xlws.FILTER(Info!$L$2:$L$6,Info!$L$2:$L$6<>"")} -> #NAME? | P1: Governorate | R1: {=_xlws.FILTER(Info!$P$2:$P$21,Info!$P$2:$P$21<>"")} -> #NAME? | T1: Sites | V1: {=_xlws.FILTER(Info!$T$2:$T$14,Info!$T$2:$T$14<>"")} -> #NAME?
A2: FM- NCD | B2: ANC | C2: Dressing | D2: Screeining | E2: Screeining | L2: Male | P2: North Gaza | T2: Gaza Clinic
A3: FM- CD | B3: PNC | C3: Follow-up Dressing | D3: Screeining and Referral | E3: SAM referal | L3: Female | P3: Gaza City | T3: Nussirat Clinic
A4: ENT | B4: FP | C4: Wound Cleaning | E4: MAM referal | P4: Alzahra City | T4: Berka Clinic
A5: Derma | B5: GYN | C5: Suture Removal | P5: Alnussirat | T5: Hiker Clinic
P6: Alburaij | T6: Jameel Wadie Clinic
P7: Almaghazi | T7: Majidah Clinic
J8: ACHA | P8: Almusadar
J9: CFTA | P9: Alzawida
P10: Dier Albalah
P11: Khanyounis City
I12: Displaced | P12: Khanyouni- Almawasi
I13: Host Community | P13: Rafah

Sheet General Overview
A1: consulations
B2: Males | F2: Females | J2: Total
A3: Service | B3: (0-5) | C3: (6-18) | D3: (19-60) | E3: (+60) | F3: (0-5) | G3: (6-18) | H3: (19-60) | I3: (+60)
A4: FM- CD | B4: #REF! | C4: #REF! | D4: #REF! | E4: #REF! | F4: #REF! | G4: #REF! | H4: #REF! | I4: #REF! | J4: =SUM(B4:I4) -> #REF!
A5: FM-NCD | B5: #REF! | C5: #REF! | D5: #REF! | E5: #REF! | F5: #REF! | G5: #REF! | H5: #REF! | I5: #REF! | J5: =SUM(B5:I5) -> #REF!
A6: Derma | B6: #REF! | C6: #REF! | D6: #REF! | E6: #REF! | F6: #REF! | G6: #REF! | H6: #REF! | I6: #REF! | J6: =SUM(B6:I6) -> #REF!
A7: ENT | B7: #REF! | C7: #REF! | D7: #REF! | E7: #REF! | F7: #REF! | G7: #REF! | H7: #REF! | I7: #REF! | J7: =SUM(B7:I7) -> #REF!
A8: SRH-ANC | B8: #VALUE! | C8: #VALUE! | D8: #VALUE! | E8: #VALUE! | F8: #VALUE! | G8: #VALUE! | H8: #VALUE! | I8: #VALUE! | J8: =SUM(B8:I8) -> #VALUE!
A9: SRH-PNC | B9: #VALUE! | C9: #VALUE! | D9: #VALUE! | E9: #VALUE! | F9: #VALUE! | G9: #VALUE! | H9: #VALUE! | I9: #VALUE! | J9: =SUM(B9:I9) -> #VALUE!
A10: SRH-FP | B10: #VALUE! | C10: #VALUE! | D10: #VALUE! | E10: #VALUE! | F10: #VALUE! | G10: #VALUE! | H10: #VALUE! | I10: #VALUE! | J10: =SUM(B10:I10) -> #VALUE!
A11: SRH-Gynea Care | B11: #VALUE! | C11: #VALUE! | D11: #VALUE! | E11: #VALUE! | F11: #VALUE! | G11: #VALUE! | H11: #VALUE! | I11: #VALUE! | J11: =SUM(B11:I11) -> #VALUE!
A12: SRH- Other | B12: #VALUE! | C12: #VALUE! | D12: #VALUE! | E12: #VALUE! | F12: #VALUE! | G12: #VALUE! | H12: #VALUE! | I12: #VALUE! | J12: =SUM(B12:I12) -> #VALUE!
A13: Totals | B13: =SUM(B4:B12) -> #REF! | C13: =SUM(C4:C12) -> #REF! | D13: =SUM(D4:D12) -> #REF! | E13: =SUM(E4:E12) -> #REF! | F13: =SUM(F4:F12) -> #REF! | G13: =SUM(G4:G12) -> #REF! | H13: =SUM(H4:H12) -> #REF! | I13: =SUM(I4:I12) -> #REF! | J13: =SUM(B13:I13) -> #REF!

Sheet Dashboard
A1: Services | J1: Displacement tracker | K1: Count of Displacment Tracker
A2: FM service | C2: SRH Service | E2: Wound Care | G2: Breast Cancer | J2: Grand Total
A3: FM service | B3: Total Consulations | C3: SRH Service | D3: Total SRH Consulations | E3: Wound Care | F3: Total of Wound Care | G3: Breast Cancer | H3: Total of Breast Cancer
A4: Total Consulations | C4: Total Consulations | E4: Grand Total | G4: Grand Total
A9: Age Groups | B9: Total Consulations | C9: Agr Groups Vs SRH services | D9: Total SRH Consulations | E9: Row Labels | F9: Total of Wound Care | G9: Row Labels | H9: Total of Breast Cancer
A10: Total Patients | C10: Grand Total | E10: Grand Total | G10: Grand Total
A15: Gender | B15: Total Consulations | C15: Row Labels | D15: Total SRH Consulations | E15: Row Labels | F15: Total of Wound Care | G15: Row Labels | H15: Total of Breast Cancer
A16: Total Pateints | C16: Grand Total | E16: Grand Total | G16: Grand Total
A19: PWD | B19: Total Consulations | C19: Row Labels | D19: Total SRH Consulations | E19: Row Labels | F19: Total of Wound Care | G19: Row Labels | H19: Total of Breast Cancer
A20: Total Patients | C20: Grand Total | E20: Grand Total | G20: Grand Total
